Workbook

Sheet Caracterizacao
A1: Determinacao densidade
A2: Amostra | C2: m0 (g) | D2: m1 (g) | E2: m1 - m0 (g) | F2: V (L) | G2: m2 (g) | H2: m2 – m0 (g) | I2: densidade (g/L) | J2: densidade padrao (g/L)
A3: RA | B3: 1 | C3: 136 | D3: 235 | E3: =D3-C3 -> 99 | F3: =E3/$C$9 -> 0.099177528 | G3: 242 | H3: =G3-C3 -> 106 | I3: =H3/F3 -> 1068.7905 | J3: =MEDIAN(I3:I4) -> 1068.4376
B4: 2 | C4: 116 | D4: 216 | E4: =D4-C4 -> 100 | F4: =E4/$C$9 -> 0.10017932 | G4: 223 | H4: =G4-C4 -> 107 | I4: =H4/F4 -> 1068.0847
A5: GL | B5: 1 | C5: 114.21 | D5: 213.96 | E5: =D5-C5 -> 99.75 | F5: =E5/$C$9 -> 0.099928873 | G5: 203.47 | H5: =G5-C5 -> 89.26 | I5: =H5/F5 -> 893.23533 | J5: =MEDIAN(I5:I6) -> 893.07404
B6: 2 | C6: 115.74 | D6: 214.9 | E6: =D6-C6 -> 99.16 | F6: =E6/$C$9 -> 0.099337815 | G6: 204.44 | H6: =G6-C6 -> 88.7 | I6: =H6/F6 -> 892.91274
A7: Inoculo | B7: 1 | C7: 136 | D7: 235 | E7: =D7-C7 -> 99 | F7: =E7/$C$9 -> 0.099177528 | G7: 242 | H7: =G7-C7 -> 106 | I7: =H7/F7 -> 1068.7905 | J7: =MEDIAN(I7:I8) -> 1068.4376
B8: 2 | C8: 116 | D8: 216 | E8: =D8-C8 -> 100 | F8: =E8/$C$9 -> 0.10017932 | G8: 223 | H8: =G8-C8 -> 107 | I8: =H8/F8 -> 1068.0847
A9: Densidade agua (g/L) | C9: 998.21
A12: Determinacao de Solidos
A13: Amostra | C13: m0 (g) | D13: m1 (g) | E13: m sub (g) | F13: V sub (L) | G13: m2 (g) | H13: TS (g/L) | I13: media TS (g/L) | J13: TS % | K13: media TS % | L13: m3 (g) | M13: VS (g/L) | N13: media VS (g/L) | O13: VS % | P13: media VS % | Q13: FS (g/L) | R13: media FS (g/L) | S13: FS % | T13: media FS %
A14: RA | B14: 1 | C14: 78.731 | D14: =105.9875 -> 105.9875 | E14: =D14-C14 -> 27.2565 | F14: =E14/$J$3 -> 0.025510615 | G14: 91.0021 | H14: =((G14-C14))/(F14) -> 481.01938 | I14: =MEDIAN(H14:H16) -> 536.39975 | J14: =((G14-C14)*100)/(D14-C14) -> 45.020821 | K14: =MEDIAN(J14:J16) -> 50.204125 | L14: 79.2024 | M14: =(G14-L14)/F14 -> 462.54079 | N14: =MEDIAN(M14:M16) -> 520.80678 | O14: =((G14-L14)*100)/(G14-C14) -> 96.158454 | P14: =MEDIAN(O14:O16) -> 96.239828 | Q14: =(L14-C14)/F14 -> 18.478583 | R14: =MEDIAN(Q14:Q16) -> 18.478583 | S14: =((L14-C14)*100)/(G14-C14) -> 3.8415464 | T14: =MEDIAN(S14:S16) -> 3.7601716
B15: 2 | C15: 84.3206 | D15: =113.2979 -> 113.2979 | E15: =D15-C15 -> 28.9773 | F15: =E15/$J$3 -> 0.027121191 | G15: 98.8684 | H15: =((G15-C15))/(F15) -> 536.39975 | J15: =((G15-C15)*100)/(D15-C15) -> 50.204125 | L15: 84.7435 | M15: =(G15-L15)/F15 -> 520.80678 | O15: =((G15-L15)*100)/(G15-C15) -> 97.093031 | Q15: =(L15-C15)/F15 -> 15.592973 | S15: =((L15-C15)*100)/(G15-C15) -> 2.9069688
B16: 3 | C16: 77.5887 | D16: =108.8399 -> 108.8399 | E16: =D16-C16 -> 31.2512 | F16: =E16/$J$3 -> 0.029249439 | G16: 93.4417 | H16: =((G16-C16))/(F16) -> 541.99331 | J16: =((G16-C16)*100)/(D16-C16) -> 50.727652 | L16: 78.1848 | M16: =(G16-L16)/F16 -> 521.61343 | O16: =((G16-L16)*100)/(G16-C16) -> 96.239828 | Q16: =(L16-C16)/F16 -> 20.379878 | S16: =((L16-C16)*100)/(G16-C16) -> 3.7601716
A17: GL | B17: 1 | C17: 84.2193 | D17: =88.6434 -> 88.6434 | E17: =D17-C17 -> 4.4241 | F17: =E17/$J$5 -> 0.0049537886 | G17: 88.4966 | H17: =((G17-C17))/(F17) -> 863.44015 | I17: =MEDIAN(H17:H19) -> 867.72399 | J17: =((G17-C17)*100)/(D17-C17) -> 96.681811 | K17: =MEDIAN(J17:J19) -> 97.161485 | L17: 84.2144 | M17: =(G17-L17)/F17 -> 864.42929 | N17: =MEDIAN(M17:M19) -> 868.65482 | O17: =((G17-L17)*100)/(G17-C17) -> 100.11456 | P17: =MEDIAN(O17:O19) -> 100.11456 | Q17: =(L17-C17)/F17 -> -0.98914192 | R17: =MEDIAN(Q17:Q19) -> -0.98914192 | S17: =((L17-C17)*100)/(G17-C17) -> -0.11455825 | T17: =MEDIAN(S17:S19) -> -0.11455825
B18: 2 | C18: 73.478 | D18: =77.9874 -> 77.9874 | E18: =D18-C18 -> 4.5094 | F18: =E18/$J$5 -> 0.0050493014 | G18: 77.8594 | H18: =((G18-C18))/(F18) -> 867.72399 | J18: =((G18-C18)*100)/(D18-C18) -> 97.161485 | L18: 73.4733 | M18: =(G18-L18)/F18 -> 868.65482 | O18: =((G18-L18)*100)/(G18-C18) -> 100.10727 | Q18: =(L18-C18)/F18 -> -0.93082183 | S18: =((L18-C18)*100)/(G18-C18) -> -0.10727165
B19: 3 | C19: 86.2012 | D19: =90.6107 -> 90.6107 | E19: =D19-C19 -> 4.4095 | F19: =E19/$J$5 -> 0.0049374406 | G19: 90.5034 | H19: =((G19-C19))/(F19) -> 871.34213 | J19: =((G19-C19)*100)/(D19-C19) -> 97.566618 | L19: 86.1958 | M19: =(G19-L19)/F19 -> 872.43581 | O19: =((G19-L19)*100)/(G19-C19) -> 100.12552 | Q19: =(L19-C19)/F19 -> -1.093684 | S19: =((L19-C19)*100)/(G19-C19) -> -0.12551718
A20: Inoculo | B20: 1 | C20: 78.731 | D20: =105.9875 -> 105.9875 | E20: =D20-C20 -> 27.2565 | F20: =E20/$J$7 -> 0.025510615 | G20: 91.0021 | H20: =((G20-C20))/(F20) -> 481.01938 | I20: =MEDIAN(H20:H22) -> 536.39975 | J20: =((G20-C20)*100)/(D20-C20) -> 45.020821 | K20: =MEDIAN(J20:J22) -> 50.204125 | L20: 79.2024 | M20: =(G20-L20)/F20 -> 462.54079 | N20: =MEDIAN(M20:M22) -> 520.80678 | O20: =((G20-L20)*100)/(G20-C20) -> 96.158454 | P20: =MEDIAN(O20:O22) -> 96.239828 | Q20: =(L20-C20)/F20 -> 18.478583 | R20: =MEDIAN(Q20:Q22) -> 18.478583 | S20: =((L20-C20)*100)/(G20-C20) -> 3.8415464 | T20: =MEDIAN(S20:S22) -> 3.7601716
B21: 2 | C21: 84.3206 | D21: =113.2979 -> 113.2979 | E21: =D21-C21 -> 28.9773 | F21: =E21/$J$7 -> 0.027121191 | G21: 98.8684 | H21: =((G21-C21))/(F21) -> 536.39975 | J21: =((G21-C21)*100)/(D21-C21) -> 50.204125 | L21: 84.7435 | M21: =(G21-L21)/F21 -> 520.80678 | O21: =((G21-L21)*100)/(G21-C21) -> 97.093031 | Q21: =(L21-C21)/F21 -> 15.592973 | S21: =((L21-C21)*100)/(G21-C21) -> 2.9069688
B22: 3 | C22: 77.5887 | D22: =108.8399 -> 108.8399 | E22: =D22-C22 -> 31.2512 | F22: =E22/$J$7 -> 0.029249439 | G22: 93.4417 | H22: =((G22-C22))/(F22) -> 541.99331 | J22: =((G22-C22)*100)/(D22-C22) -> 50.727652 | L22: 78.1848 | M22: =(G22-L22)/F22 -> 521.61343 | O22: =((G22-L22)*100)/(G22-C22) -> 96.239828 | Q22: =(L22-C22)/F22 -> 20.379878 | S22: =((L22-C22)*100)/(G22-C22) -> 3.7601716
C23: 71.7136 | D23: 94.3466 | G23: 71.7446 | L23: 71.7204
C24: 78.4856 | D24: 103.4794 | G24: 81.8396 | L24: 78.4935
C25: 73.2435 | D25: 96.3926 | G25: 76.1155 | L25: 73.2506
A26: Resultado TOC
A27: Amostra | C27: TOC (mg/L) | D27: TC (mg/L) | E27: IC (mg/L) | F27: TN (mg/L) | G27: diluicao | H27: TC (mg/L) | I27: media TC (mg/L) | J27: IC (mg/L) | K27: media IC (mg/L) | L27: TN (mg/L) | M27: media TN (mg/L)
A28: RA | B28: 1 | C28: 5.039 | D28: 5.044 | E28: 0.00562 | F28: 0.6891 | G28: 400 | H28: =D28*G28 -> 2017.6 | I28: =MEDIAN(H28:H29) -> 1778.6 | J28: =E28*G28 -> 2.248 | K28: =MEDIAN(J28:J29) -> 16.68 | L28: =F28*G28 -> 275.64 | M28: =MEDIAN(L28:L29) -> 281.76
B29: 2 | C29: 3.927 | D29: 3.849 | E29: 0.07778 | F29: 0.7197 | G29: 400 | H29: =D29*G29 -> 1539.6 | J29: =E29*G29 -> 31.112 | L29: =F29*G29 -> 287.88
A30: GL | B30: 1 | C30: 8.808 | D30: 8.812 | E30: 0.00431 | F30: 0.5875 | G30: 800 | H30: =D30*G30 -> 7049.6 | I30: =MEDIAN(H30:H31) -> 5523.2 | J30: =E30*G30 -> 3.448 | K30: =MEDIAN(J30:J31) -> 3.228 | L30: =F30*G30 -> 470 | M30: =MEDIAN(L30:L31) -> 488.6
B31: 2 | C31: 4.992 | D31: 4.996 | E31: 0.00376 | F31: 0.634 | G31: 800 | H31: =D31*G31 -> 3996.8 | J31: =E31*G31 -> 3.008 | L31: =F31*G31 -> 507.2

Sheet COV
A1: Substrato | B1: Densidade (g/L) | C1: TC (g/L) | D1: TN (g/L) | E1: TS (g/L) | F1: VS (g/L) | J1: Sub 1 | K1: Sub 2 | O1: Sub 1 | P1: Sub 2
A2: RA | B2: =Caracterizacao!J3 -> 1068.4376 | C2: =Caracterizacao!I28/1000 -> 1.7786 | D2: =Caracterizacao!M28/1000 -> 0.28176 | E2: =Caracterizacao!I14 -> 536.39975 | F2: =Caracterizacao!N14 -> 520.80678 | I2: Substrato | J2: GL – BIO | K2: GL – PURO | N2: Diluicao | O2: 1 | P2: 100
A3: GL – BIO | B3: =Caracterizacao!J5 -> 893.07404 | C3: =Caracterizacao!I30/1000 -> 5.5232 | D3: =Caracterizacao!M30/1000 -> 0.4886 | E3: =Caracterizacao!I17 -> 867.72399 | F3: =Caracterizacao!N17 -> 868.65482 | I3: Densidade (g/L) | J3: =INDEX($B$2:$B$100,MATCH($J$2,$A$2:$A$100,0)) -> 893.07404 | K3: =INDEX($B$2:$B$100,MATCH($K$2,$A$2:$A$100,0)) -> 1260 | N3: Densidade ajustada (g/L) | O3: =J3 -> 893.07404 | P3: =K3 -> 1260
A4: GL – PURO | B4: 1260 | C4: 493 | D4: 0 | E4: 1000 | F4: 1000 | I4: TC (g/L) | J4: =INDEX($C$2:$C$100,MATCH($J$2,$A$2:$A$100,0)) -> 5.5232 | K4: =INDEX($C$2:$C$100,MATCH($K$2,$A$2:$A$100,0)) -> 493 | N4: TC ajustado (g/L) | O4: =J4/$O$2 -> 5.5232 | P4: =K4/$P$2 -> 4.93
A5: Glucose | B5: 1540 | C5: 616 | D5: 0 | E5: 1540 | F5: 1540 | I5: TN (g/L) | J5: =INDEX($D$2:$D$100,MATCH($J$2,$A$2:$A$100,0)) -> 0.4886 | K5: =INDEX($D$2:$D$100,MATCH($K$2,$A$2:$A$100,0)) -> 0 | N5: TN ajustado (g/L) | O5: =J5/$O$2 -> 0.4886 | P5: =K5/$P$2 -> 0
I6: TS (g/L) | J6: =INDEX($E$2:$E$100,MATCH($J$2,$A$2:$A$100,0)) -> 867.72399 | K6: =INDEX($E$2:$E$100,MATCH($K$2,$A$2:$A$100,0)) -> 1000 | N6: TS ajustado (g/L) | O6: =J6/$O$2 -> 867.72399 | P6: =K6/$P$2 -> 10
I7: VS (g/L) | J7: =INDEX($F$2:$F$100,MATCH($J$2,$A$2:$A$100,0)) -> 868.65482 | K7: =INDEX($F$2:$F$100,MATCH($K$2,$A$2:$A$100,0)) -> 1000 | N7: VS ajustado (g/L) | O7: =J7/$O$2 -> 868.65482 | P7: =K7/$P$2 -> 10
I10: C/N Calculation
I12: Proporcao
I13: C | J13: 25
I14: N | J14: 1 | L14: Volume Ratio Parts
I15: C/N | J15: =J13/J14 -> 25 | L15: =((J15*P5)-P4) -> -4.93
I16: Volume Ratio (L) | J16: =((J15*P5)-P4)/(O4-(J15*O5)) -> 0.73672256 | L16: =(O4-(J15*O5)) -> -6.6918
I18: - | J18: Volume (L) | K18: From V Ratio (L) | L18: Volume (mL) | M18: Quantidade Carbono (g) | O18: Concentracao Carbono (g/L)
I19: Sub 1 | J19: - | K19: =J16*J20 -> 0.73672256 | L19: =K19*1000 -> 736.72256 | M19: =K19*O4 -> 4.069066 | O19: -
I20: Sub 2 | J20: 1 | K20: - | L20: =J20*1000 -> 1000 | M20: =J20*P4 -> 4.93 | O20: -
I21: Mistura | J21: =J20+K19 -> 1.7367226 | K21: - | L21: =J21*1000 -> 1736.7226 | M21: =M19+M20 -> 8.999066 | O21: =M21/J21 -> 5.1816371
I22: Sub 1 | J22: 1 | K22: - | L22: =J22*1000 -> 1000 | M22: =J22*O3 -> 893.07404 | O22: -
I23: Sub 2 | J23: - | K23: =J22/J16 -> 1.3573631 | L23: =K23*1000 -> 1357.3631 | M23: =K23*P3 -> 1710.2775 | O23: -
I24: Mistura | J24: =J22+K23 -> 2.3573631 | K24: - | L24: =J24*1000 -> 2357.3631 | M24: =M22+M23 -> 2603.3515 | O24: =M24/J24 -> 1104.349
I27: Calculo ST e SV
I29: - | J29: Mass (g) | K29: Total Mass (g) | L29: TS (g) | M29: TS % | N29: VS (g) | O29: VS % | P29: VS/TS
I30: Sub 1 | J30: =K19*O3 -> 657.94779 | K30: =J30+J31 -> 1917.9478 | L30: =($O$6*K19)+($P$6*J20) -> 649.27184 | M30: =(L30/K30)*100 -> 33.852425 | N30: =($O$7*K19)+($P$7*J20) -> 649.9576 | O30: =(N30/K30)*100 -> 33.88818 | P30: =N30/L30 -> 1.0010562
I31: Sub 2 | J31: =J20*P3 -> 1260
I32: Sub 1 | J32: =J22*O3 -> 893.07404 | K32: =J32+J33 -> 2603.3515 | L32: =($O$6*K23)+($P$6*J22) -> 1187.8165 | M32: =(L32/K32)*100 -> 45.626436 | N32: =($O$7*K23)+($P$7*J22) -> 1189.08 | O32: =(N32/K32)*100 -> 45.674968 | P32: =N32/L32 -> 1.0010637
I33: Sub 2 | J33: =K23*P3 -> 1710.2775
I35: TS % Alvo | K35: TS % Ratio | L35: VS diluido (g) | M35: Volume (L) | N35: VS diluido (g/L)
I36: 8 | K36: =M30/$I$36 -> 4.2315531 | L36: =N30/K36 -> 153.59788 | M36: =K36*J21 -> 7.3490338 | N36: =L36/M36 -> 20.900418
I37: 10 | K37: =M30/$I$37 -> 3.3852425 | L37: =N30/K37 -> 191.99735 | M37: =K37*J21 -> 5.879227 | N37: =L37/M37 -> 32.656904
K38: =M32/$I$36 -> 5.7033045 | L38: =N32/K38 -> 208.48965 | M38: =K38*J24 -> 13.444759 | N38: =L38/M38 -> 15.507132
K39: =M32/$I$37 -> 4.5626436 | L39: =N32/K39 -> 260.61207 | M39: =K39*J24 -> 10.755808 | N39: =L39/M39 -> 24.229893
I42: Calculo COV
I44: Reator | J44: Volume (L) | K44: Volume (m^3) | L44: Tempo Retencao (d) | M44: Fluxo (L/d) | O44: COV Alvo
I45: Reator Pequeno 1 | J45: 1 | K45: =J45/1000 -> 0.001 | L45: 30 | M45: =J45/L45 -> 0.033333333 | O45: 4
I46: Reator Pequeno 2 | J46: 1 | K46: =J46/1000 -> 0.001 | L46: 3 | M46: =J46/L46 -> 0.33333333 | O46: 14.2
I47: Reator Grande | J47: 4 | K47: =J47/1000 -> 0.004 | L47: 12 | M47: =J47/L47 -> 0.33333333 | O47: 2.6
I50: VS (g/d) | J50: VS (Kg/d) | K50: COV (Kg SV/m³ d) | N50: COV Ratio | O50: Volume (L) | P50: TS % diluido
I51: =$M$45*$N$36 -> 0.69668061 | J51: =I51/1000 -> 0.00069668061 | K51: =J51*(1/K45) -> 0.69668061 | N51: =K51/$O$45 -> 0.17417015 | O51: =N51*$M$36 -> 1.2799823 | P51: =($M$30*$J$21)/O51 -> 45.932095
I52: =$M$46*$N$36 -> 6.9668061 | J52: =I52/1000 -> 0.0069668061 | K52: =J52*(1/K46) -> 6.9668061 | N52: =K52/$O$46 -> 0.49062015 | O52: =N52*$M$36 -> 3.6055841 | P52: =($M$30*$J$21)/O52 -> 16.305894
I53: =$M$47*$N$36 -> 6.9668061 | J53: =I53/1000 -> 0.0069668061 | K53: =J53*(1/K47) -> 1.7417015 | N53: =K53/$O$47 -> 0.6698852 | O53: =N53*$M$36 -> 4.923009 | P53: =($M$30*$J$21)/O53 -> 11.942345
...

Sheet COV_3
A1: Substrato | B1: Densidade (g/L) | C1: TC (g/L) | D1: TN (g/L) | E1: TS (g/L) | F1: VS (g/L) | J1: Sub 1 | K1: Sub 2 | L1: Sub 3 | O1: Sub 1 | P1: Sub 2 | Q1: Sub 2
A2: RA | B2: =Caracterizacao!J3 -> 1068.4376 | C2: =Caracterizacao!I28/1000 -> 1.7786 | D2: =Caracterizacao!M28/1000 -> 0.28176 | E2: =Caracterizacao!I14 -> 536.39975 | F2: =Caracterizacao!N14 -> 520.80678 | I2: Substrato | J2: GL – BIO | K2: GL – BIO | L2: GL – PURO | N2: Diluicao | O2: 1 | P2: 1 | Q2: 100
A3: GL – BIO | B3: =Caracterizacao!J5 -> 893.07404 | C3: =Caracterizacao!I30/1000 -> 5.5232 | D3: =Caracterizacao!M30/1000 -> 0.4886 | E3: =Caracterizacao!I17 -> 867.72399 | F3: =Caracterizacao!N17 -> 868.65482 | I3: Densidade (g/L) | J3: =INDEX($B$2:$B$100,MATCH($J$2,$A$2:$A$100,0)) -> 893.07404 | K3: =INDEX($B$2:$B$100,MATCH($K$2,$A$2:$A$100,0)) -> 893.07404 | L3: =INDEX($B$2:$B$100,MATCH($L$2,$A$2:$A$100,0)) -> 1260 | N3: Densidade ajustada (g/L) | O3: =J3 -> 893.07404 | P3: =K3 -> 893.07404 | Q3: =L3 -> 1260
A4: GL – PURO | B4: 1260 | C4: 493 | D4: 0 | E4: 1000 | F4: 1000 | I4: TC (g/L) | J4: =INDEX($C$2:$C$100,MATCH($J$2,$A$2:$A$100,0)) -> 5.5232 | K4: =INDEX($C$2:$C$100,MATCH($K$2,$A$2:$A$100,0)) -> 5.5232 | L4: =INDEX($C$2:$C$100,MATCH($L$2,$A$2:$A$100,0)) -> 493 | N4: TC ajustado (g/L) | O4: =J4/$O$2 -> 5.5232 | P4: =K4/$P$2 -> 5.5232 | Q4: =L4/$Q$2 -> 4.93
A5: Glucose | B5: 1540 | C5: 616 | D5: 0 | E5: 1540 | F5: 1540 | I5: TN (g/L) | J5: =INDEX($D$2:$D$100,MATCH($J$2,$A$2:$A$100,0)) -> 0.4886 | K5: =INDEX($D$2:$D$100,MATCH($K$2,$A$2:$A$100,0)) -> 0.4886 | L5: =INDEX($D$2:$D$100,MATCH($L$2,$A$2:$A$100,0)) -> 0 | N5: TN ajustado (g/L) | O5: =J5/$O$2 -> 0.4886 | P5: =K5/$P$2 -> 0.4886 | Q5: =L5/$Q$2 -> 0
I6: TS (g/L) | J6: =INDEX($E$2:$E$100,MATCH($J$2,$A$2:$A$100,0)) -> 867.72399 | K6: =INDEX($E$2:$E$100,MATCH($K$2,$A$2:$A$100,0)) -> 867.72399 | L6: =INDEX($E$2:$E$100,MATCH($L$2,$A$2:$A$100,0)) -> 1000 | N6: TS ajustado (g/L) | O6: =J6/$O$2 -> 867.72399 | P6: =K6/$P$2 -> 867.72399 | Q6: =L6/$Q$2 -> 10
I7: VS (g/L) | J7: =INDEX($F$2:$F$100,MATCH($J$2,$A$2:$A$100,0)) -> 868.65482 | K7: =INDEX($F$2:$F$100,MATCH($K$2,$A$2:$A$100,0)) -> 868.65482 | L7: =INDEX($F$2:$F$100,MATCH($L$2,$A$2:$A$100,0)) -> 1000 | N7: VS ajustado (g/L) | O7: =J7/$O$2 -> 868.65482 | P7: =K7/$P$2 -> 868.65482 | Q7: =L7/$Q$2 -> 10
I10: C/N Calculation
I12: Proporcao | L12: - | M12: Volume (L) | N12: Multiplicador (g/L) | O12: Value (g/L)
I13: C | J13: 25 | L13: Sub 1 | M13: 1 | N13: =O$4-($J$15*O$5) -> -6.6918 | O13: =N13*M13 -> -6.6918
I14: N | J14: 1 | L14: Sub 2 | M14: 1 | N14: =P$4-($J$15*P$5) -> -6.6918 | O14: =N14*M14 -> -6.6918
I15: C/N | J15: =J13/J14 -> 25 | L15: Sub 3 | M15: 0.5 | N15: =Q$4-($J$15*Q$5) -> 4.93 | O15: =N15*M15 -> 2.465
I18: - | J18: Volume (L) | K18: Volume (mL) | L18: Quantidade Carbono (g) | N18: Concentracao Carbono (g/L)
I19: Sub 1 | J19: =$M$13 -> 1 | K19: =$J19*1000 -> 1000 | L19: =$J19*$O$4 -> 5.5232 | N19: =$L19/$J19 -> 5.5232
I20: Sub 2 | J20: =$M$14 -> 1 | K20: =$J20*1000 -> 1000 | L20: =$J20*$P$4 -> 5.5232 | N20: =$L20/$J20 -> 5.5232
I21: Sub 3 | J21: =($O$13-$O$14)/$N$15 -> 0 | K21: =$J21*1000 -> 0 | L21: =$J21*$Q$4 -> 0 | N21: =$L21/$J21 -> #DIV/0!
I22: Mistura | J22: =SUM(J19:J21) -> 2 | K22: =SUM(K19:K21) -> 2000 | L22: =SUM($L19:$L21) -> 11.0464 | N22: =$L22/$J22 -> 5.5232
I23: Sub 1 | J23: =$M$13 -> 1 | K23: =$J23*1000 -> 1000 | L23: =$J23*$O$4 -> 5.5232 | N23: =$L23/$J23 -> 5.5232
I24: Sub 2 | J24: =$M$14 -> 1 | K24: =$J24*1000 -> 1000 | L24: =$J24*$P$4 -> 5.5232 | N24: =$L24/$J24 -> 5.5232
I25: Sub 3 | J25: =($O$14-$O$13)/$N$15 -> 0 | K25: =$J25*1000 -> 0 | L25: =$J25*$Q$4 -> 0 | N25: =$L25/$J25 -> #DIV/0!
I26: Mistura | J26: =SUM(J23:J25) -> 2 | K26: =SUM(K23:K25) -> 2000 | L26: =SUM($L23:$L25) -> 11.0464 | N26: =$L26/$J26 -> 5.5232
I27: Sub 1 | J27: =$M$13 -> 1 | K27: =$J27*1000 -> 1000 | L27: =$J27*$O$4 -> 5.5232 | N27: =$L27/$J27 -> 5.5232
I28: Sub 2 | J28: =($O$13-$O$15)/$N$14 -> 1.3683613 | K28: =$J28*1000 -> 1368.3613 | L28: =$J28*$P$4 -> 7.557733 | N28: =$L28/$J28 -> 5.5232
I29: Sub 3 | J29: =$M$15 -> 0.5 | K29: =$J29*1000 -> 500 | L29: =$J29*$Q$4 -> 2.465 | N29: =$L29/$J29 -> 4.93
I30: Mistura | J30: =SUM(J27:J29) -> 2.8683613 | K30: =SUM(K27:K29) -> 2868.3613 | L30: =SUM($L27:$L29) -> 15.545933 | N30: =$L30/$J30 -> 5.419796
I31: Sub 1 | J31: =$M$13 -> 1 | K31: =$J31*1000 -> 1000 | L31: =$J31*$O$4 -> 5.5232 | N31: =$L31/$J31 -> 5.5232
I32: Sub 2 | J32: =($O$15-$O$13)/$N$14 -> -1.3683613 | K32: =$J32*1000 -> -1368.3613 | L32: =$J32*$P$4 -> -7.557733 | N32: =$L32/$J32 -> 5.5232
I33: Sub 3 | J33: =$M$15 -> 0.5 | K33: =$J33*1000 -> 500 | L33: =$J33*$Q$4 -> 2.465 | N33: =$L33/$J33 -> 4.93
I34: Mistura | J34: =SUM(J31:J33) -> 0.13163872 | K34: =SUM(K31:K33) -> 131.63872 | L34: =SUM($L31:$L33) -> 0.43046699 | N34: =$L34/$J34 -> 3.2700636
I35: Sub 1 | J35: =($O$14-$O$15)/$N$13 -> 1.3683613 | K35: =$J35*1000 -> 1368.3613 | L35: =$J35*$O$4 -> 7.557733 | N35: =$L35/$J35 -> 5.5232
I36: Sub 2 | J36: =$M$14 -> 1 | K36: =$J36*1000 -> 1000 | L36: =$J36*$P$4 -> 5.5232 | N36: =$L36/$J36 -> 5.5232
I37: Sub 3 | J37: =$M$15 -> 0.5 | K37: =$J37*1000 -> 500 | L37: =$J37*$Q$4 -> 2.465 | N37: =$L37/$J37 -> 4.93
I38: Mistura | J38: =SUM(J35:J37) -> 2.8683613 | K38: =SUM(K35:K37) -> 2868.3613 | L38: =SUM($L35:$L37) -> 15.545933 | N38: =$L38/$J38 -> 5.419796
I39: Sub 1 | J39: =($O$15-$O$14)/$N$13 -> -1.3683613 | K39: =$J39*1000 -> -1368.3613 | L39: =$J39*$O$4 -> -7.557733 | N39: =$L39/$J39 -> 5.5232
I40: Sub 2 | J40: =$M$14 -> 1 | K40: =$J40*1000 -> 1000 | L40: =$J40*$P$4 -> 5.5232 | N40: =$L40/$J40 -> 5.5232
I41: Sub 3 | J41: =$M$15 -> 0.5 | K41: =$J41*1000 -> 500 | L41: =$J41*$Q$4 -> 2.465 | N41: =$L41/$J41 -> 4.93
I42: Mistura | J42: =SUM(J39:J41) -> 0.13163872 | K42: =SUM(K39:K41) -> 131.63872 | L42: =SUM($L39:$L41) -> 0.43046699 | N42: =$L42/$J42 -> 3.2700636
I45: Calculo ST e SV
I47: Substrato | J47: Mass (g) | K47: Total Mass (g) | L47: TS (g) | M47: TS % | N47: VS (g) | O47: VS % | P47: VS/TS
I48: Sub 1 | J48: =$J19*$O$3 -> 893.07404 | K48: =SUM(J48:J50) -> 1786.1481 | L48: =($O$6*$J19)+($P$6*$J20)+($Q$6*$J21) -> 1735.448 | M48: =($L48/$K48)*100 -> 97.161485 | N48: =($O$7*$J19)+($P$7*$J20)+($Q$7*$J21) -> 1737.3096 | O48: =($N48/$K48)*100 -> 97.265712 | P48: =$N48/$L48 -> 1.0010727
...

Sheet Calibracao Bombas
A1: bomba grande A | B1: mL/min | C1: rpm | D1: volume (mL) | J1: bomba pequena | L1: rpm | M1: volume (mL)
A2: Diogenes | B2: 0.3133 | C2: 0.1 | D2: 0.3 | L2: 1 | M2: 1.5
B3: 0.4 | C3: 0.128 | D3: 0.4 | L3: 5 | M3: 4
B4: 0.5 | C4: 0.16 | D4: 0.45 | L4: 10 | M4: 8.9
B5: 0.6 | C5: 0.191 | D5: 0.59 | L5: 15 | M5: 13.3
B6: 0.75 | C6: 0.239 | D6: 0.67 | L6: 20 | M6: 17.5
B7: 0.8 | C7: 0.255 | D7: 0.92 | L7: 30 | M7: 26
B8: 0.9 | C8: 0.287 | D8: 1.14 | L8: 50 | M8: 44
B9: 1 | C9: 0.319 | D9: 1.16 | L9: 80 | M9: 69
B10: 1.25 | C10: 0.399 | D10: 1.35 | L10: 100 | M10: 87
B11: 1.5 | C11: 0.479 | D11: 1.43 | L11: 120 | M11: 104
B12: 1.75 | C12: 0.559 | D12: 1.67 | L12: 200 | M12: 168
A25: bomba grande B | B25: mL/min | C25: rpm | D25: volume (mL) | J25: bomba grande C | K25: mL/min | L25: rpm | M25: volume (mL)
A26: Verena entrada | B26: 2 | C26: 0.67 | D26: 1.8 | J26: medido em 30 s | K26: 1 | L26: 0.949 | M26: 3
B27: 2.5 | C27: 0.837 | D27: 2.4 | J27: Verena saida | K27: 1.5 | L27: 1.424 | M27: 3.8
B28: 2.8 | C28: 0.938 | D28: 3 | K28: 1.8 | L28: 1.709 | M28: 5
B29: 3 | C29: 1.004 | D29: 3.2 | K29: 2 | L29: 1.899 | M29: 5.6
B30: 3.5 | C30: 1.172 | D30: 3.6 | K30: 2.5 | L30: 2.373 | M30: 6.8
B31: 4 | C31: 1.339 | D31: 4.2 | K31: 3 | L31: 2.848 | M31: 8.5
B32: 4.5 | C32: 1.507 | D32: 4.8 | K32: 3.5 | L32: 3.323 | M32: 10.5
B33: 5 | C33: 1.674 | D33: 5.4 | K33: 4 | L33: 3.797 | M33: 11.5
B34: 5.5 | C34: 1.842 | D34: 6 | K34: 4.5 | L34: 4.272 | M34: 13.4
B35: 6 | C35: 2.009 | D35: 6.4 | K35: 5 | L35: 4.747 | M35: 15
B36: 6.5 | C36: 2.176 | D36: 7.2 | K36: 5.5 | L36: 5.222 | M36: 17
H53: verena
E54: reator diogenes | H54: reator pequeno | K54: reator grande
A55: quant ativacoes | B55: 1 | D55: tempo rentencao (dia) | E55: 30 | H55: 3 | K55: 12
A56: tempo ativacao (min) | B56: 4 | D56: volume (mL) | E56: 1000 | H56: 1000 | K56: 4000
D57: volume/dia (mL) | E57: =E56/E55 -> 33.333333 | H57: =H56/H55 -> 333.33333 | K57: =K56/K55 -> 333.33333
A58: quant ativacoes | B58: 20 | D58: volume/ativacao (mL) | E58: =E57/$B$55 -> 33.333333 | H58: =H57/$B$58 -> 16.666667 | K58: =K57/$B$58 -> 16.666667
A59: tempo ativacao (min) | B59: 5 | D59: volume/minuto (mL) | E59: =E58/$B$56 -> 8.3333333 | H59: =H58/$B$59 -> 3.3333333 | K59: =K58/$B$59 -> 3.3333333
D60: curva bomba a | E60: {=LINEST(C2:C12,D2:D12)} -> 0.30530654 | F60: 0.0035009131 | H60: {=LINEST(C26:C36,D26:D36)} -> 0.2878668 | I60: 0.12276304 | K60: {=LINEST(L26:L36,M26:M36)} -> 0.30092866 | L60: 0.22182191
D61: rpm | E61: =(E59*E60)+F60 -> 2.5477221 | H61: =(H59*H60)+I60 -> 1.0823191 | K61: =(K59*K60)+L60 -> 1.2249174
D62: Curva 2 bomba a | E62: {=LINEST(B2:B12,C2:C12)} -> 3.1310818 | F62: 0.00062263595 | H62: {=LINEST(B26:B36,C26:C36)} -> 2.9869976 | I62: -0.00061635236 | K62: {=LINEST(K26:K36,L26:L36)} -> 1.0532563 | L62: 0.00025585954
D63: mL/min | E63: =(E62*E61)+F62 -> 7.9777491 | H63: =(H62*H61)+I62 -> 3.2322681 | K63: =(K62*K61)+L62 -> 1.2904079

Sheet Nutrientes
A1: Nutrientes | B1: Mass (mg/350ml) | C1: Adição (mg/L) | D1: Adição (g/L) | E1: X100 (g/L) | F1: X1000 (g/L) | G1: X2000 (g/L) | H1: Código
A2: MgSO4.7H2O | B2: 18.9 | C2: =((B2*1000)/350) -> 54 | D2: =((B2*1000)/350)/1000 -> 0.054 | E2: =D2*100 -> 5.4 | F2: =D2*1000 -> 54 | G2: =D2*2000 -> 108 | H2: 5.5.1
A3: FeSO4.7H2O | B3: 522.8 | C3: =((B3*1000)/350) -> 1493.7143 | D3: =((B3*1000)/350)/1000 -> 1.4937143 | E3: =D3*100 -> 149.37143 | F3: =D3*1000 -> 1493.7143 | G3: =D3*2000 -> 2987.4286 | H3: 5.4.1
A4: CoCl2.6H2O | B4: 0.42 | C4: =((B4*1000)/350) -> 1.2 | D4: =((B4*1000)/350)/1000 -> 0.0012 | E4: =D4*100 -> 0.12 | F4: =D4*1000 -> 1.2 | G4: =D4*2000 -> 2.4 | H4: 2.5.4
A5: ZnCl2 | B5: 10.5 | C5: =((B5*1000)/350) -> 30 | D5: =((B5*1000)/350)/1000 -> 0.03 | E5: =D5*100 -> 3 | F5: =D5*1000 -> 30 | G5: =D5*2000 -> 60 | H5: sem num
A6: NiCl2.6H2O | B6: 0.0105 | C6: =((B6*1000)/350) -> 0.03 | D6: =((B6*1000)/350)/1000 -> 3e-05 | E6: =D6*100 -> 0.003 | F6: =D6*1000 -> 0.03 | G6: =D6*2000 -> 0.06 | H6: 2.5.8
A7: EDTA | B7: 0.21 | C7: =((B7*1000)/350) -> 0.6 | D7: =((B7*1000)/350)/1000 -> 0.0006 | E7: =D7*100 -> 0.06 | F7: =D7*1000 -> 0.6 | G7: =D7*2000 -> 1.2 | H7: 1.2.1
A8: CuSO4.5H2O | B8: 9.23 | C8: =((B8*1000)/350) -> 26.371429 | D8: =((B8*1000)/350)/1000 -> 0.026371429 | E8: =D8*100 -> 2.6371429 | F8: =D8*1000 -> 26.371429 | G8: =D8*2000 -> 52.742857 | H8: 5.3.1
A11: mL | B11: g/L
A12: 500 | B12: 1X | C12: 100X | D12: 1000X | E12: 2000X
A13: MgSO4.7H2O | B13: =D2*($A$12/1000) -> 0.027 | C13: =(E2*$A$12)/1000 -> 2.7 | D13: =(F2*$A$12)/1000 -> 27 | E13: =(G2*$A$12)/1000 -> 54
A14: FeSO4.7H2O | B14: =D3*($A$12/1000) -> 0.74685714 | C14: =(E3*$A$12)/1000 -> 74.685714 | D14: =(F3*$A$12)/1000 -> 746.85714 | E14: =(G3*$A$12)/1000 -> 1493.7143
A15: CoCl2.6H2O | B15: =D4*($A$12/1000) -> 0.0006 | C15: =(E4*$A$12)/1000 -> 0.06 | D15: =(F4*$A$12)/1000 -> 0.6 | E15: =(G4*$A$12)/1000 -> 1.2
A16: ZnCl2 | B16: =D5*($A$12/1000) -> 0.015 | C16: =(E5*$A$12)/1000 -> 1.5 | D16: =(F5*$A$12)/1000 -> 15 | E16: =(G5*$A$12)/1000 -> 30
A17: NiCl2.6H2O | B17: =D6*($A$12/1000) -> 1.5e-05 | C17: =(E6*$A$12)/1000 -> 0.0015 | D17: =(F6*$A$12)/1000 -> 0.015 | E17: =(G6*$A$12)/1000 -> 0.03
A18: EDTA | B18: =D7*($A$12/1000) -> 0.0003 | C18: =(E7*$A$12)/1000 -> 0.03 | D18: =(F7*$A$12)/1000 -> 0.3 | E18: =(G7*$A$12)/1000 -> 0.6
A19: CuSO4.5H2O | B19: =D8*($A$12/1000) -> 0.013185714 | C19: =(E8*$A$12)/1000 -> 1.3185714 | D19: =(F8*$A$12)/1000 -> 13.185714 | E19: =(G8*$A$12)/1000 -> 26.371429
A20: mL | B20: =C20*100 -> 500 | C20: =D20*10 -> 5 | D20: =1*(A12/1000) -> 0.5 | E20: =D20/2 -> 0.25
A23: mL | B23: g/L
A24: 250 | B24: 1X | C24: 100X | D24: 1000X | E24: 2000X
A25: MgSO4.7H2O | B25: =D2*($A$24/1000) -> 0.0135 | C25: =(E2*$A$24)/1000 -> 1.35 | D25: =(F2*$A$24)/1000 -> 13.5 | E25: =(G2*$A$24)/1000 -> 27
A26: FeSO4.7H2O | B26: =D3*($A$24/1000) -> 0.37342857 | C26: =(E3*$A$24)/1000 -> 37.342857 | D26: =(F3*$A$24)/1000 -> 373.42857 | E26: =(G3*$A$24)/1000 -> 746.85714
A27: CoCl2.6H2O | B27: =D4*($A$24/1000) -> 0.0003 | C27: =(E4*$A$24)/1000 -> 0.03 | D27: =(F4*$A$24)/1000 -> 0.3 | E27: =(G4*$A$24)/1000 -> 0.6
A28: ZnCl2 | B28: =D5*($A$24/1000) -> 0.0075 | C28: =(E5*$A$24)/1000 -> 0.75 | D28: =(F5*$A$24)/1000 -> 7.5 | E28: =(G5*$A$24)/1000 -> 15
A29: NiCl2.6H2O | B29: =D6*($A$24/1000) -> 7.5e-06 | C29: =(E6*$A$24)/1000 -> 0.00075 | D29: =(F6*$A$24)/1000 -> 0.0075 | E29: =(G6*$A$24)/1000 -> 0.015
A30: EDTA | B30: =D7*($A$24/1000) -> 0.00015 | C30: =(E7*$A$24)/1000 -> 0.015 | D30: =(F7*$A$24)/1000 -> 0.15 | E30: =(G7*$A$24)/1000 -> 0.3
A31: CuSO4.5H2O | B31: =D8*($A$24/1000) -> 0.0065928571 | C31: =(E8*$A$24)/1000 -> 0.65928571 | D31: =(F8*$A$24)/1000 -> 6.5928571 | E31: =(G8*$A$24)/1000 -> 13.185714
A32: mL | B32: =C32*100 -> 250 | C32: =D32*10 -> 2.5 | D32: =1*(A24/1000) -> 0.25 | E32: =D32/2 -> 0.125
A35: mL | B35: g/L
A36: 1000 | B36: 1X | C36: 100X | D36: 1000X | E36: 2000X
A37: MgSO4.7H2O | B37: =D2*($A$36/1000) -> 0.054 | C37: =(E2*$A$36)/1000 -> 5.4 | D37: =(F2*$A$36)/1000 -> 54 | E37: =(G2*$A$36)/1000 -> 108
A38: FeSO4.7H2O | B38: =D3*($A$36/1000) -> 1.4937143 | C38: =(E3*$A$36)/1000 -> 149.37143 | D38: =(F3*$A$36)/1000 -> 1493.7143 | E38: =(G3*$A$36)/1000 -> 2987.4286
A39: CoCl2.6H2O | B39: =D4*($A$36/1000) -> 0.0012 | C39: =(E4*$A$36)/1000 -> 0.12 | D39: =(F4*$A$36)/1000 -> 1.2 | E39: =(G4*$A$36)/1000 -> 2.4
A40: ZnCl2 | B40: =D5*($A$36/1000) -> 0.03 | C40: =(E5*$A$36)/1000 -> 3 | D40: =(F5*$A$36)/1000 -> 30 | E40: =(G5*$A$36)/1000 -> 60
A41: NiCl2.6H2O | B41: =D6*($A$36/1000) -> 3e-05 | C41: =(E6*$A$36)/1000 -> 0.003 | D41: =(F6*$A$36)/1000 -> 0.03 | E41: =(G6*$A$36)/1000 -> 0.06
A42: EDTA | B42: =D7*($A$36/1000) -> 0.0006 | C42: =(E7*$A$36)/1000 -> 0.06 | D42: =(F7*$A$36)/1000 -> 0.6 | E42: =(G7*$A$36)/1000 -> 1.2
A43: CuSO4.5H2O | B43: =D8*($A$36/1000) -> 0.026371429 | C43: =(E8*$A$36)/1000 -> 2.6371429 | D43: =(F8*$A$36)/1000 -> 26.371429 | E43: =(G8*$A$36)/1000 -> 52.742857
A44: mL | B44: =C44*100 -> 1000 | C44: =D44*10 -> 10 | D44: =1*(A36/1000) -> 1 | E44: =D44/2 -> 0.5

Sheet Alcalinidade-AGV
A1: Dados | C1: Calculo Alcalinidade | G1: Calculo AGV
A2: Data | B2: volume amostra (mL) | C2: pH inicial | D2: Volume Acido (mL) | E2: Alcalinidade (mg CaCO3/L) | F2: N acido | G2: pH inicial | H2: Volume Base (mL) | I2: AGV (mg CH3COOH/L) | J2: N base | K2: AGV/Alcalinidade
A3: 22/05/2026 | B3: 50 | C3: 6.25 | D3: 4.2 | E3: =(D3*F3*50000)/B3 -> 420 | F3: 0.1 | G3: 4.05 | H3: 3.95 | I3: =(H3*J3*60000)/B3 -> 474 | J3: 0.1 | K3: =I3/E3 -> 1.1285714
A4: 26/05/2026 | B4: 50 | C4: 5.78 | D4: 10.5 | E4: =(D4*F4*50000)/B4 -> 1050 | F4: 0.1 | G4: 4.01 | H4: 11.3 | I4: =(H4*J4*60000)/B4 -> 1356 | J4: 0.1 | K4: =I4/E4 -> 1.2914286
A5: 29/05/2026 | B5: 50 | C5: 7.89 | D5: =25+25+25+0.4 -> 75.4 | E5: =(D5*F5*50000)/B5 -> 7540 | F5: 0.1 | G5: 4.01 | H5: 21.55 | I5: =(H5*J5*60000)/B5 -> 2586 | J5: 0.1 | K5: =I5/E5 -> 0.34297082
A6: 46028 | B6: 50 | C6: 7.65 | D6: =25+25+25+6.45 -> 81.45 | E6: =(D6*F6*50000)/B6 -> 8145 | F6: 0.1 | G6: 4.01 | H6: =25+4.95 -> 29.95 | I6: =(H6*J6*60000)/B6 -> 3594 | J6: 0.1 | K6: =I6/E6 -> 0.4412523
A7: 46148 | B7: 50 | C7: 7.62 | D7: 7.05 | E7: =(D7*F7*50000)/B7 -> 7050 | F7: 1 | G7: 4.06 | H7: 3.45 | I7: =(H7*J7*60000)/B7 -> 4140 | J7: 1 | K7: =I7/E7 -> 0.58723404
A8: 46240 | B8: 50 | C8: 7.56 | D8: 7 | E8: =(D8*F8*50000)/B8 -> 7000 | F8: 1 | G8: 4.02 | H8: 3.95 | I8: =(H8*J8*60000)/B8 -> 4740 | J8: 1 | K8: =I8/E8 -> 0.67714286
A9: 46362 | B9: 50 | C9: 7.58 | D9: 6.7 | E9: =(D9*F9*50000)/B9 -> 6700 | F9: 1 | G9: 4.03 | H9: 4.25 | I9: =(H9*J9*60000)/B9 -> 5100 | J9: 1 | K9: =I9/E9 -> 0.76119403
A10: 15/06/2026 | B10: 50 | C10: 7.55 | D10: 5.85 | E10: =(D10*F10*50000)/B10 -> 5850 | F10: 1 | G10: 4.03 | H10: 3.8 | I10: =(H10*J10*60000)/B10 -> 4560 | J10: 1 | K10: =I10/E10 -> 0.77948718
A11: 19/06/2026 | B11: 50 | C11: 7.32 | D11: 5.65 | E11: =(D11*F11*50000)/B11 -> 5650 | F11: 1 | G11: 4.04 | H11: 3.9 | I11: =(H11*J11*60000)/B11 -> 4680 | J11: 1 | K11: =I11/E11 -> 0.82831858
A12: 22/06/2026 | B12: 50 | C12: 7.35 | D12: 5.05 | E12: =(D12*F12*50000)/B12 -> 5050 | F12: 1 | G12: 4.02 | H12: 3.6 | I12: =(H12*J12*60000)/B12 -> 4320 | J12: 1 | K12: =I12/E12 -> 0.85544554
A13: 26/06/2026 | B13: 50 | C13: 6.98 | D13: 5 | E13: =(D13*F13*50000)/B13 -> 5000 | F13: 1 | G13: 4.02 | H13: 4.15 | I13: =(H13*J13*60000)/B13 -> 4980 | J13: 1 | K13: =I13/E13 -> 0.996
A14: 29/06/2026 | B14: 50 | C14: 7.23 | D14: 4.5 | E14: =(D14*F14*50000)/B14 -> 4500 | F14: 1 | G14: 4 | H14: 3.75 | I14: =(H14*J14*60000)/B14 -> 4500 | J14: 1 | K14: =I14/E14 -> 1
A15: 46088 | B15: 50 | C15: 6.65 | D15: 4.4 | E15: =(D15*F15*50000)/B15 -> 4400 | F15: 1 | G15: 4.01 | H15: 3.95 | I15: =(H15*J15*60000)/B15 -> 4740 | J15: 1 | K15: =I15/E15 -> 1.0772727
A16: 46180 | B16: 50 | C16: 6.53 | D16: 4.6 | E16: =(D16*F16*50000)/B16 -> 4600 | F16: 1 | G16: 4.03 | H16: 4.2 | I16: =(H16*J16*60000)/B16 -> 5040 | J16: 1 | K16: =I16/E16 -> 1.0956522
A17: 46302 | B17: 50 | C17: 6.28 | D17: 4.4 | E17: =(D17*F17*50000)/B17 -> 4400 | F17: 1 | G17: 4.02 | H17: 4.3 | I17: =(H17*J17*60000)/B17 -> 5160 | J17: 1 | K17: =I17/E17 -> 1.1727273
A18: 13/07/2026 | B18: 50 | C18: 6.16 | D18: 4.15 | E18: =(D18*F18*50000)/B18 -> 4150 | F18: 1 | G18: 4.08 | H18: 4.05 | I18: =(H18*J18*60000)/B18 -> 4860 | J18: 1 | K18: =I18/E18 -> 1.1710843
A19: 17/07/2026 | B19: 50 | C19: 6.5 | D19: 4.15 | E19: =(D19*F19*50000)/B19 -> 4150 | F19: 1 | G19: 4.03 | H19: 4.05 | I19: =(H19*J19*60000)/B19 -> 4860 | J19: 1 | K19: =I19/E19 -> 1.1710843
A20: 20/07/2026 | B20: 50 | C20: 6.48 | D20: 4.25 | E20: =(D20*F20*50000)/B20 -> 4250 | F20: 1 | G20: 4.02 | H20: 4 | I20: =(H20*J20*60000)/B20 -> 4800 | J20: 1 | K20: =I20/E20 -> 1.1294118
A21: 24/07/2026 | B21: 50 | C21: 6.75 | D21: 3.6 | E21: =(D21*F21*50000)/B21 -> 3600 | F21: 1 | G21: 4.01 | H21: 3.3 | I21: =(H21*J21*60000)/B21 -> 3960 | J21: 1 | K21: =I21/E21 -> 1.1
A22: 27/07/2026 | B22: 50 | C22: 6.88 | D22: 3.95 | E22: =(D22*F22*50000)/B22 -> 3950 | F22: 1 | G22: 4.07 | H22: 3.45 | I22: =(H22*J22*60000)/B22 -> 4140 | J22: 1 | K22: =I22/E22 -> 1.0481013
A23: 31/07/2026 | B23: 50 | C23: 7.31 | D23: 3.45 | E23: =(D23*F23*50000)/B23 -> 3450 | F23: 1 | G23: 4.08 | H23: 2.75 | I23: =(H23*J23*60000)/B23 -> 3300 | J23: 1 | K23: =I23/E23 -> 0.95652174
A24: 46089 | B24: 50 | C24: 7.21 | D24: 3.95 | E24: =(D24*F24*50000)/B24 -> 3950 | F24: 1 | G24: 4 | H24: 3.2 | I24: =(H24*J24*60000)/B24 -> 3840 | J24: 1 | K24: =I24/E24 -> 0.9721519
A25: 46211 | B25: 50 | C25: 7.2 | D25: 4.05 | E25: =(D25*F25*50000)/B25 -> 4050 | F25: 1 | G25: 4.08 | H25: 2.9 | I25: =(H25*J25*60000)/B25 -> 3480 | J25: 1 | K25: =I25/E25 -> 0.85925926
E26: =(D26*F26*50000)/B26 -> #DIV/0! | I26: =(H26*J26*60000)/B26 -> #DIV/0! | K26: =I26/E26 -> #DIV/0!
E27: =(D27*F27*50000)/B27 -> #DIV/0! | I27: =(H27*J27*60000)/B27 -> #DIV/0! | K27: =I27/E27 -> #DIV/0!
E28: =(D28*F28*50000)/B28 -> #DIV/0! | I28: =(H28*J28*60000)/B28 -> #DIV/0! | K28: =I28/E28 -> #DIV/0!
E29: =(D29*F29*50000)/B29 -> #DIV/0! | I29: =(H29*J29*60000)/B29 -> #DIV/0! | K29: =I29/E29 -> #DIV/0!
E30: =(D30*F30*50000)/B30 -> #DIV/0! | I30: =(H30*J30*60000)/B30 -> #DIV/0! | K30: =I30/E30 -> #DIV/0!
E31: =(D31*F31*50000)/B31 -> #DIV/0! | I31: =(H31*J31*60000)/B31 -> #DIV/0! | K31: =I31/E31 -> #DIV/0!
E32: =(D32*F32*50000)/B32 -> #DIV/0! | I32: =(H32*J32*60000)/B32 -> #DIV/0! | K32: =I32/E32 -> #DIV/0!
E33: =(D33*F33*50000)/B33 -> #DIV/0! | I33: =(H33*J33*60000)/B33 -> #DIV/0! | K33: =I33/E33 -> #DIV/0!
E34: =(D34*F34*50000)/B34 -> #DIV/0! | I34: =(H34*J34*60000)/B34 -> #DIV/0! | K34: =I34/E34 -> #DIV/0!
E35: =(D35*F35*50000)/B35 -> #DIV/0! | I35: =(H35*J35*60000)/B35 -> #DIV/0! | K35: =I35/E35 -> #DIV/0!

Sheet Production-total
A2: Day | B2: Volume (NmL) | C2: Flow (nML/d) | E2: Hour | F2: Volume (NmL) | G2: Flow (nML/h) | I2: Hour | J2: Volume (NmL) | K2: Flow (nML/h)
A3: 0 | B3: 0 | C3: 0 | E3: 0 | F3: 0 | G3: 0 | I3: 0 | J3: 0 | K3: 0
A4: 1 | B4: 0 | C4: 0 | E4: 1 | F4: 0 | G4: 0 | I4: 0.25 | J4: 0 | K4: 0
A5: 2 | B5: 0 | C5: 0 | E5: 2 | F5: 0 | G5: 0 | I5: 0.5 | J5: 0 | K5: 0
A6: 3 | B6: 1.1 | C6: 1.1 | E6: 3 | F6: 0 | G6: 0 | I6: 0.75 | J6: 0 | K6: 0
A7: 4 | B7: 9.1 | C7: 8 | E7: 4 | F7: 0 | G7: 0 | I7: 1 | J7: 0 | K7: 0
A8: 5 | B8: 13.4 | C8: 4.4 | E8: 5 | F8: 0 | G8: 0 | I8: 1.25 | J8: 0 | K8: 0
A9: 6 | B9: 29.8 | C9: 16.4 | E9: 6 | F9: 0 | G9: 0 | I9: 1.5 | J9: 0 | K9: 0
A10: 7 | B10: 55.8 | C10: 25.9 | E10: 7 | F10: 0 | G10: 0 | I10: 1.75 | J10: 0 | K10: 0
A11: 8 | B11: 124.6 | C11: 68.9 | E11: 8 | F11: 0 | G11: 0 | I11: 2 | J11: 0 | K11: 0
A12: 9 | B12: 149.1 | C12: 24.4 | E12: 9 | F12: 0 | G12: 0 | I12: 2.25 | J12: 0 | K12: 0
A13: 10 | B13: 217.4 | C13: 68.3 | E13: 10 | F13: 0 | G13: 0 | I13: 2.5 | J13: 0 | K13: 0
A14: 11 | B14: 267.9 | C14: 50.5 | E14: 11 | F14: 0 | G14: 0 | I14: 2.75 | J14: 0 | K14: 0
... A84: 81 | B84: 2885.9 | C84: 16.1 | E84: 81 | F84: 1.5 | G84: 0.1 | I84: 20.25 | J84: 0 | K84: 0
E85: 82 | F85: 1.6 | G85: 0.1 | I85: 20.5 | J85: 0 | K85: 0
E86: 83 | F86: 1.6 | G86: 0.1 | I86: 20.75 | J86: 0 | K86: 0
E87: 84 | F87: 1.7 | G87: 0.1 | I87: 21 | J87: 0 | K87: 0
E88: 85 | F88: 1.7 | G88: 0.1 | I88: 21.25 | J88: 0 | K88: 0
E89: 86 | F89: 1.8 | G89: 0.1 | I89: 21.5 | J89: 0 | K89: 0
E90: 87 | F90: 1.8 | G90: 0.1 | I90: 21.75 | J90: 0 | K90: 0
E91: 88 | F91: 1.9 | G91: 0.1 | I91: 22 | J91: 0 | K91: 0
E92: 89 | F92: 1.9 | G92: 0.1 | I92: 22.25 | J92: 0 | K92: 0
E93: 90 | F93: 2 | G93: 0.1 | I93: 22.5 | J93: 0 | K93: 0
E94: 91 | F94: 2 | G94: 0.1 | I94: 22.75 | J94: 0 | K94: 0
E95: 92 | F95: 2.5 | G95: 0.5 | I95: 23 | J95: 0 | K95: 0
E96: 93 | F96: 3.1 | G96: 0.6 | I96: 23.25 | J96: 0 | K96: 0
... E1945: 1942 | F1945: 2885.9 | G1945: 3.1 | I1945: 485.5 | J1945: 651.6 | K1945: 1
I1946: 485.75 | J1946: 651.8 | K1946: 1
I1947: 486 | J1947: 652.1 | K1947: 1
I1948: 486.25 | J1948: 652.3 | K1948: 1
I1949: 486.5 | J1949: 652.6 | K1949: 0.9
I1950: 486.75 | J1950: 652.7 | K1950: 0.6
I1951: 487 | J1951: 652.8 | K1951: 0.6
I1952: 487.25 | J1952: 653 | K1952: 0.6
I1953: 487.5 | J1953: 653.1 | K1953: 0.6
I1954: 487.75 | J1954: 653.3 | K1954: 0.6
I1955: 488 | J1955: 653.4 | K1955: 0.6
I1956: 488.25 | J1956: 653.5 | K1956: 0.6
I1957: 488.5 | J1957: 653.7 | K1957: 0.6
... I7769: 1941.5 | J7769: 2885.9 | K7769: 3.1

Sheet Production-RA
A2: Day | B2: Volume (NmL) | C2: Flow (nML/d) | E2: Hour | F2: Volume (NmL) | G2: Flow (nML/h) | I2: Hour | J2: Volume (NmL) | K2: Flow (nML/h)
A3: 0 | B3: 0 | C3: 0 | E3: 0 | F3: 0 | G3: 0 | I3: 0 | J3: 0 | K3: 0
A4: 1 | B4: 0 | C4: 0 | E4: 1 | F4: 0 | G4: 0 | I4: 0.25 | J4: 0 | K4: 0
A5: 2 | B5: 0 | C5: 0 | E5: 2 | F5: 0 | G5: 0 | I5: 0.5 | J5: 0 | K5: 0
A6: 3 | B6: 1.1 | C6: 1.1 | E6: 3 | F6: 0 | G6: 0 | I6: 0.75 | J6: 0 | K6: 0
A7: 4 | B7: 9.1 | C7: 8 | E7: 4 | F7: 0 | G7: 0 | I7: 1 | J7: 0 | K7: 0
A8: 5 | B8: 13.4 | C8: 4.4 | E8: 5 | F8: 0 | G8: 0 | I8: 1.25 | J8: 0 | K8: 0
A9: 6 | B9: 29.8 | C9: 16.4 | E9: 6 | F9: 0 | G9: 0 | I9: 1.5 | J9: 0 | K9: 0
A10: 7 | B10: 55.8 | C10: 25.9 | E10: 7 | F10: 0 | G10: 0 | I10: 1.75 | J10: 0 | K10: 0
A11: 8 | B11: 124.6 | C11: 68.9 | E11: 8 | F11: 0 | G11: 0 | I11: 2 | J11: 0 | K11: 0
A12: 9 | B12: 149.1 | C12: 24.4 | E12: 9 | F12: 0 | G12: 0 | I12: 2.25 | J12: 0 | K12: 0
A13: 10 | B13: 217.4 | C13: 68.3 | E13: 10 | F13: 0 | G13: 0 | I13: 2.5 | J13: 0 | K13: 0
A14: 11 | B14: 267.9 | C14: 50.5 | E14: 11 | F14: 0 | G14: 0 | I14: 2.75 | J14: 0 | K14: 0
... A55: 52 | B55: 2008.8 | C55: 54 | E55: 52 | F55: 0 | G55: 0 | I55: 13 | J55: 0 | K55: 0
E56: 53 | F56: 0 | G56: 0 | I56: 13.25 | J56: 0 | K56: 0
E57: 54 | F57: 0 | G57: 0 | I57: 13.5 | J57: 0 | K57: 0
E58: 55 | F58: 0 | G58: 0 | I58: 13.75 | J58: 0 | K58: 0
E59: 56 | F59: 0 | G59: 0 | I59: 14 | J59: 0 | K59: 0
E60: 57 | F60: 0 | G60: 0 | I60: 14.25 | J60: 0 | K60: 0
E61: 58 | F61: 0 | G61: 0 | I61: 14.5 | J61: 0 | K61: 0
E62: 59 | F62: 0 | G62: 0 | I62: 14.75 | J62: 0 | K62: 0
E63: 60 | F63: 0 | G63: 0 | I63: 15 | J63: 0 | K63: 0
E64: 61 | F64: 0 | G64: 0 | I64: 15.25 | J64: 0 | K64: 0
E65: 62 | F65: 0 | G65: 0 | I65: 15.5 | J65: 0 | K65: 0
E66: 63 | F66: 0 | G66: 0 | I66: 15.75 | J66: 0 | K66: 0
E67: 64 | F67: 0 | G67: 0 | I67: 16 | J67: 0 | K67: 0
... E1251: 1248 | F1251: 2008.8 | G1251: 5.1 | I1251: 312 | J1251: 350.2 | K1251: 3.1
I1252: 312.25 | J1252: 350.7 | K1252: 1.8
I1253: 312.5 | J1253: 351.1 | K1253: 1.8
I1254: 312.75 | J1254: 351.6 | K1254: 1.8
I1255: 313 | J1255: 352 | K1255: 1.8
I1256: 313.25 | J1256: 352.5 | K1256: 1.8
I1257: 313.5 | J1257: 353 | K1257: 1.8
I1258: 313.75 | J1258: 353.4 | K1258: 1.8
I1259: 314 | J1259: 353.9 | K1259: 1.8
I1260: 314.25 | J1260: 354.3 | K1260: 1.8
I1261: 314.5 | J1261: 354.8 | K1261: 1.8
I1262: 314.75 | J1262: 355.2 | K1262: 1.8
I1263: 315 | J1263: 355.7 | K1263: 1.8
... I4998: 1248.75 | J4998: 2012.4 | K4998: 3.3

Sheet Production-GL
A2: Day | B2: Volume (NmL) | C2: Flow (nML/d) | E2: Hour | F2: Volume (NmL) | G2: Flow (nML/h) | I2: Hour | J2: Volume (NmL) | K2: Flow (nML/h)
A3: =A36 -> 53 | B3: =B36-$A$34 -> 106.7 | C3: =C36 -> 106.7 | E3: =E678 -> 1272 | F3: =F678-$E$676 -> 3.7 | G3: =G678 -> 3.6 | I3: =I2686 -> 1272 | J3: =J2686-$I$2684 -> 0.1 | K3: =K2686 -> 0.3
A4: =A37 -> 54 | B4: =B37-$A$34 -> 128.2 | C4: =C37 -> 21.5 | E4: =E679 -> 1273 | F4: =F679-$E$676 -> 4 | G4: =G679 -> 0.3 | I4: =I2687 -> 1272.25 | J4: =J2687-$I$2684 -> 0.2 | K4: =K2687 -> 0.3
A5: =A38 -> 55 | B5: =B38-$A$34 -> 179.8 | C5: =C38 -> 51.6 | E5: =E680 -> 1274 | F5: =F680-$E$676 -> 4.3 | G5: =G680 -> 0.3 | I5: =I2688 -> 1272.5 | J5: =J2688-$I$2684 -> 0.3 | K5: =K2688 -> 0.3
A6: =A39 -> 56 | B6: =B39-$A$34 -> 216.3 | C6: =C39 -> 36.5 | E6: =E681 -> 1275 | F6: =F681-$E$676 -> 4.7 | G6: =G681 -> 0.3 | I6: =I2689 -> 1272.75 | J6: =J2689-$I$2684 -> 0.3 | K6: =K2689 -> 0.3
A7: =A40 -> 57 | B7: =B40-$A$34 -> 252.7 | C7: =C40 -> 36.4 | E7: =E682 -> 1276 | F7: =F682-$E$676 -> 5 | G7: =G682 -> 0.3 | I7: =I2690 -> 1273 | J7: =J2690-$I$2684 -> 0.4 | K7: =K2690 -> 0.3
A8: =A41 -> 58 | B8: =B41-$A$34 -> 282.2 | C8: =C41 -> 29.5 | E8: =E683 -> 1277 | F8: =F683-$E$676 -> 5.3 | G8: =G683 -> 0.3 | I8: =I2691 -> 1273.25 | J8: =J2691-$I$2684 -> 0.5 | K8: =K2691 -> 0.3
A9: =A42 -> 59 | B9: =B42-$A$34 -> 311.6 | C9: =C42 -> 29.3 | E9: =E684 -> 1278 | F9: =F684-$E$676 -> 5.6 | G9: =G684 -> 0.3 | I9: =I2692 -> 1273.5 | J9: =J2692-$I$2684 -> 0.6 | K9: =K2692 -> 0.3
A10: =A43 -> 60 | B10: =B43-$A$34 -> 326.7 | C10: =C43 -> 15.1 | E10: =E685 -> 1279 | F10: =F685-$E$676 -> 5.9 | G10: =G685 -> 0.3 | I10: =I2693 -> 1273.75 | J10: =J2693-$I$2684 -> 0.7 | K10: =K2693 -> 0.3
A11: =A44 -> 61 | B11: =B44-$A$34 -> 357.2 | C11: =C44 -> 30.6 | E11: =E686 -> 1280 | F11: =F686-$E$676 -> 6.3 | G11: =G686 -> 0.3 | I11: =I2694 -> 1274 | J11: =J2694-$I$2684 -> 0.7 | K11: =K2694 -> 0.3
A12: =A45 -> 62 | B12: =B45-$A$34 -> 387.7 | C12: =C45 -> 30.5 | E12: =E687 -> 1281 | F12: =F687-$E$676 -> 6.6 | G12: =G687 -> 0.3 | I12: =I2695 -> 1274.25 | J12: =J2695-$I$2684 -> 0.8 | K12: =K2695 -> 0.3
A13: =A46 -> 63 | B13: =B46-$A$34 -> 403.5 | C13: =C46 -> 15.8 | E13: =E688 -> 1282 | F13: =F688-$E$676 -> 6.9 | G13: =G688 -> 0.3 | I13: =I2696 -> 1274.5 | J13: =J2696-$I$2684 -> 0.9 | K13: =K2696 -> 0.3
A14: =A47 -> 64 | B14: =B47-$A$34 -> 433.7 | C14: =C47 -> 30.3 | E14: =E689 -> 1283 | F14: =F689-$E$676 -> 7.2 | G14: =G689 -> 0.3 | I14: =I2697 -> 1274.75 | J14: =J2697-$I$2684 -> 1 | K14: =K2697 -> 0.3
... A31: =A64 -> 81 | B31: =B64-$A$34 -> 877.1 | C31: =C64 -> 16.1 | E31: =E706 -> 1300 | F31: =F706-$E$676 -> 34.5 | G31: =G706 -> 1.7 | I31: =I2714 -> 1279 | J31: =J2714-$I$2684 -> 2.3 | K31: =K2714 -> 0.3
E32: =E707 -> 1301 | F32: =F707-$E$676 -> 36.2 | G32: =G707 -> 1.7 | I32: =I2715 -> 1279.25 | J32: =J2715-$I$2684 -> 2.4 | K32: =K2715 -> 0.3
A33: acumulated before (NmL) | E33: =E708 -> 1302 | F33: =F708-$E$676 -> 37.9 | G33: =G708 -> 1.7 | I33: =I2716 -> 1279.5 | J33: =J2716-$I$2684 -> 2.5 | K33: =K2716 -> 0.3
A34: 2008.8 | E34: =E709 -> 1303 | F34: =F709-$E$676 -> 39.5 | G34: =G709 -> 1.6 | I34: =I2717 -> 1279.75 | J34: =J2717-$I$2684 -> 2.6 | K34: =K2717 -> 0.3
E35: =E710 -> 1304 | F35: =F710-$E$676 -> 40.6 | G35: =G710 -> 1.1 | I35: =I2718 -> 1280 | J35: =J2718-$I$2684 -> 2.7 | K35: =K2718 -> 0.3
A36: 53 | B36: 2115.5 | C36: 106.7 | E36: =E711 -> 1305 | F36: =F711-$E$676 -> 41.8 | G36: =G711 -> 1.1 | I36: =I2719 -> 1280.25 | J36: =J2719-$I$2684 -> 2.8 | K36: =K2719 -> 0.3
A37: 54 | B37: 2137 | C37: 21.5 | E37: =E712 -> 1306 | F37: =F712-$E$676 -> 42.9 | G37: =G712 -> 1.1 | I37: =I2720 -> 1280.5 | J37: =J2720-$I$2684 -> 2.8 | K37: =K2720 -> 0.3
A38: 55 | B38: 2188.6 | C38: 51.6 | E38: =E713 -> 1307 | F38: =F713-$E$676 -> 44 | G38: =G713 -> 1.1 | I38: =I2721 -> 1280.75 | J38: =J2721-$I$2684 -> 2.9 | K38: =K2721 -> 0.3
A39: 56 | B39: 2225.1 | C39: 36.5 | E39: =E714 -> 1308 | F39: =F714-$E$676 -> 45.1 | G39: =G714 -> 1.1 | I39: =I2722 -> 1281 | J39: =J2722-$I$2684 -> 3 | K39: =K2722 -> 0.3
A40: 57 | B40: 2261.5 | C40: 36.4 | E40: =E715 -> 1309 | F40: =F715-$E$676 -> 46.3 | G40: =G715 -> 1.1 | I40: =I2723 -> 1281.25 | J40: =J2723-$I$2684 -> 3.1 | K40: =K2723 -> 0.3
A41: 58 | B41: 2291 | C41: 29.5 | E41: =E716 -> 1310 | F41: =F716-$E$676 -> 48 | G41: =G716 -> 1.7 | I41: =I2724 -> 1281.5 | J41: =J2724-$I$2684 -> 3.2 | K41: =K2724 -> 0.3
A42: 59 | B42: 2320.4 | C42: 29.3 | E42: =E717 -> 1311 | F42: =F717-$E$676 -> 49.8 | G42: =G717 -> 1.8 | I42: =I2725 -> 1281.75 | J42: =J2725-$I$2684 -> 3.2 | K42: =K2725 -> 0.3
A43: 60 | B43: 2335.5 | C43: 15.1 | E43: =E718 -> 1312 | F43: =F718-$E$676 -> 51.6 | G43: =G718 -> 1.8 | I43: =I2726 -> 1282 | J43: =J2726-$I$2684 -> 3.3 | K43: =K2726 -> 0.3
A44: 61 | B44: 2366 | C44: 30.6 | E44: =E719 -> 1313 | F44: =F719-$E$676 -> 53.4 | G44: =G719 -> 1.8 | I44: =I2727 -> 1282.25 | J44: =J2727-$I$2684 -> 3.4 | K44: =K2727 -> 0.3
A45: 62 | B45: 2396.5 | C45: 30.5 | E45: =E720 -> 1314 | F45: =F720-$E$676 -> 55.2 | G45: =G720 -> 1.7 | I45: =I2728 -> 1282.5 | J45: =J2728-$I$2684 -> 3.5 | K45: =K2728 -> 0.3
A46: 63 | B46: 2412.3 | C46: 15.8 | E46: =E721 -> 1315 | F46: =F721-$E$676 -> 56.9 | G46: =G721 -> 1.7 | I46: =I2729 -> 1282.75 | J46: =J2729-$I$2684 -> 3.6 | K46: =K2729 -> 0.3
A47: 64 | B47: 2442.5 | C47: 30.3 | E47: =E722 -> 1316 | F47: =F722-$E$676 -> 58.6 | G47: =G722 -> 1.7 | I47: =I2730 -> 1283 | J47: =J2730-$I$2684 -> 3.6 | K47: =K2730 -> 0.3
... A64: 81 | B64: 2885.9 | C64: 16.1 | E64: =E739 -> 1333 | F64: =F739-$E$676 -> 84 | G64: =G739 -> 0.7 | I64: =I2747 -> 1287.25 | J64: =J2747-$I$2684 -> 5 | K64: =K2747 -> 0.3
E65: =E740 -> 1334 | F65: =F740-$E$676 -> 84.7 | G65: =G740 -> 0.7 | I65: =I2748 -> 1287.5 | J65: =J2748-$I$2684 -> 5.1 | K65: =K2748 -> 0.3
E66: =E741 -> 1335 | F66: =F741-$E$676 -> 85.4 | G66: =G741 -> 0.7 | I66: =I2749 -> 1287.75 | J66: =J2749-$I$2684 -> 5.2 | K66: =K2749 -> 0.3
E67: =E742 -> 1336 | F67: =F742-$E$676 -> 86.1 | G67: =G742 -> 0.7 | I67: =I2750 -> 1288 | J67: =J2750-$I$2684 -> 5.3 | K67: =K2750 -> 0.3
E68: =E743 -> 1337 | F68: =F743-$E$676 -> 86.9 | G68: =G743 -> 0.7 | I68: =I2751 -> 1288.25 | J68: =J2751-$I$2684 -> 5.3 | K68: =K2751 -> 0.3
E69: =E744 -> 1338 | F69: =F744-$E$676 -> 87.6 | G69: =G744 -> 0.7 | I69: =I2752 -> 1288.5 | J69: =J2752-$I$2684 -> 5.4 | K69: =K2752 -> 0.3
E70: =E745 -> 1339 | F70: =F745-$E$676 -> 88.3 | G70: =G745 -> 0.7 | I70: =I2753 -> 1288.75 | J70: =J2753-$I$2684 -> 5.5 | K70: =K2753 -> 0.3
E71: =E746 -> 1340 | F71: =F746-$E$676 -> 89 | G71: =G746 -> 0.7 | I71: =I2754 -> 1289 | J71: =J2754-$I$2684 -> 5.6 | K71: =K2754 -> 0.3
E72: =E747 -> 1341 | F72: =F747-$E$676 -> 89.7 | G72: =G747 -> 0.7 | I72: =I2755 -> 1289.25 | J72: =J2755-$I$2684 -> 5.7 | K72: =K2755 -> 0.3
E73: =E748 -> 1342 | F73: =F748-$E$676 -> 112.3 | G73: =G748 -> 22.6 | I73: =I2756 -> 1289.5 | J73: =J2756-$I$2684 -> 5.7 | K73: =K2756 -> 0.3
...
