Workbook

Sheet Caracterizacao
A1: Determinacao densidade
A2: Amostra | C2: m0 (g) | D2: m1 (g) | E2: m1 - m0 (g) | F2: V (L) | G2: m2 (g) | H2: m2 – m0 (g) | I2: densidade (g/L) | J2: densidade padrao (g/L)
A3: RA | B3: 1 | C3: 136 | D3: 235 | E3: =D3-C3 -> 99 | F3: =E3/$C$9 -> 0.099177528 | G3: 242 | H3: =G3-C3 -> 106 | I3: =H3/F3 -> 1068.7905 | J3: =MEDIAN(I3:I4) -> 1068.4376
B4: 2 | C4: 116 | D4: 216 | E4: =D4-C4 -> 100 | F4: =E4/$C$9 -> 0.10017932 | G4: 223 | H4: =G4-C4 -> 107 | I4: =H4/F4 -> 1068.0847
A5: GL | B5: 1 | C5: 114.21 | D5: 213.96 | E5: =D5-C5 -> 99.75 | F5: =E5/$C$9 -> 0.099928873 | G5: 203.47 | H5: =G5-C5 -> 89.26 | I5: =H5/F5 -> 893.23533 | J5: =MEDIAN(I5:I6) -> 893.07404
B6: 2 | C6: 115.74 | D6: 214.9 | E6: =D6-C6 -> 99.16 | F6: =E6/$C$9 -> 0.099337815 | G6: 204.44 | H6: =G6-C6 -> 88.7 | I6: =H6/F6 -> 892.91274
A7: Inoculo | B7: 1 | C7: 136 | D7: 235 | E7: =D7-C7 -> 99 | F7: =E7/$C$9 -> 0.099177528 | G7: 242 | H7: =G7-C7 -> 106 | I7: =H7/F7 -> 1068.7905 | J7: =MEDIAN(I7:I8) -> 1068.4376
B8: 2 | C8: 116 | D8: 216 | E8: =D8-C8 -> 100 | F8: =E8/$C$9 -> 0.10017932 | G8: 223 | H8: =G8-C8 -> 107 | I8: =H8/F8 -> 1068.0847
A9: Densidade agua (g/L) | C9: 998.21
A12: Determinacao de Solidos
A13: Amostra | C13: m0 (g) | D13: m1 (g) | E13: m sub (g) | F13: V sub (L) | G13: m2 (g) | H13: TS (g/L) | I13: media TS (g/L) | J13: TS % | K13: media TS % | L13: m3 (g) | M13: VS (g/L) | N13: media VS (g/L) | O13: VS % | P13: media VS % | Q13: FS (g/L) | R13: media FS (g/L) | S13: FS % | T13: media FS %
A14: RA | B14: 1 | C14: 78.731 | D14: =105.9875 -> 105.9875 | E14: =D14-C14 -> 27.2565 | F14: =E14/$J$3 -> 0.025510615 | G14: 91.0021 | H14: =((G14-C14))/(F14) -> 481.01938 | I14: =MEDIAN(H14:H16) -> 536.39975 | J14: =((G14-C14)*100)/(D14-C14) -> 45.020821 | K14: =MEDIAN(J14:J16) -> 50.204125 | L14: 79.2024 | M14: =(G14-L14)/F14 -> 462.54079 | N14: =MEDIAN(M14:M16) -> 520.80678 | O14: =((G14-L14)*100)/(G14-C14) -> 96.158454 | P14: =MEDIAN(O14:O16) -> 96.239828 | Q14: =(L14-C14)/F14 -> 18.478583 | R14: =MEDIAN(Q14:Q16) -> 18.478583 | S14: =((L14-C14)*100)/(G14-C14) -> 3.8415464 | T14: =MEDIAN(S14:S16) -> 3.7601716
B15: 2 | C15: 84.3206 | D15: =113.2979 -> 113.2979 | E15: =D15-C15 -> 28.9773 | F15: =E15/$J$3 -> 0.027121191 | G15: 98.8684 | H15: =((G15-C15))/(F15) -> 536.39975 | J15: =((G15-C15)*100)/(D15-C15) -> 50.204125 | L15: 84.7435 | M15: =(G15-L15)/F15 -> 520.80678 | O15: =((G15-L15)*100)/(G15-C15) -> 97.093031 | Q15: =(L15-C15)/F15 -> 15.592973 | S15: =((L15-C15)*100)/(G15-C15) -> 2.9069688
B16: 3 | C16: 77.5887 | D16: =108.8399 -> 108.8399 | E16: =D16-C16 -> 31.2512 | F16: =E16/$J$3 -> 0.029249439 | G16: 93.4417 | H16: =((G16-C16))/(F16) -> 541.99331 | J16: =((G16-C16)*100)/(D16-C16) -> 50.727652 | L16: 78.1848 | M16: =(G16-L16)/F16 -> 521.61343 | O16: =((G16-L16)*100)/(G16-C16) -> 96.239828 | Q16: =(L16-C16)/F16 -> 20.379878 | S16: =((L16-C16)*100)/(G16-C16) -> 3.7601716
A17: GL | B17: 1 | C17: 84.2193 | D17: =88.6434 -> 88.6434 | E17: =D17-C17 -> 4.4241 | F17: =E17/$J$5 -> 0.0049537886 | G17: 88.4966 | H17: =((G17-C17))/(F17) -> 863.44015 | I17: =MEDIAN(H17:H19) -> 867.72399 | J17: =((G17-C17)*100)/(D17-C17) -> 96.681811 | K17: =MEDIAN(J17:J19) -> 97.161485 | L17: 84.2144 | M17: =(G17-L17)/F17 -> 864.42929 | N17: =MEDIAN(M17:M19) -> 868.65482 | O17: =((G17-L17)*100)/(G17-C17) -> 100.11456 | P17: =MEDIAN(O17:O19) -> 100.11456 | Q17: =(L17-C17)/F17 -> -0.98914192 | R17: =MEDIAN(Q17:Q19) -> -0.98914192 | S17: =((L17-C17)*100)/(G17-C17) -> -0.11455825 | T17: =MEDIAN(S17:S19) -> -0.11455825
B18: 2 | C18: 73.478 | D18: =77.9874 -> 77.9874 | E18: =D18-C18 -> 4.5094 | F18: =E18/$J$5 -> 0.0050493014 | G18: 77.8594 | H18: =((G18-C18))/(F18) -> 867.72399 | J18: =((G18-C18)*100)/(D18-C18) -> 97.161485 | L18: 73.4733 | M18: =(G18-L18)/F18 -> 868.65482 | O18: =((G18-L18)*100)/(G18-C18) -> 100.10727 | Q18: =(L18-C18)/F18 -> -0.93082183 | S18: =((L18-C18)*100)/(G18-C18) -> -0.10727165
B19: 3 | C19: 86.2012 | D19: =90.6107 -> 90.6107 | E19: =D19-C19 -> 4.4095 | F19: =E19/$J$5 -> 0.0049374406 | G19: 90.5034 | H19: =((G19-C19))/(F19) -> 871.34213 | J19: =((G19-C19)*100)/(D19-C19) -> 97.566618 | L19: 86.1958 | M19: =(G19-L19)/F19 -> 872.43581 | O19: =((G19-L19)*100)/(G19-C19) -> 100.12552 | Q19: =(L19-C19)/F19 -> -1.093684 | S19: =((L19-C19)*100)/(G19-C19) -> -0.12551718
A20: Inoculo | B20: 1 | C20: 78.731 | D20: =105.9875 -> 105.9875 | E20: =D20-C20 -> 27.2565 | F20: =E20/$J$7 -> 0.025510615 | G20: 91.0021 | H20: =((G20-C20))/(F20) -> 481.01938 | I20: =MEDIAN(H20:H22) -> 536.39975 | J20: =((G20-C20)*100)/(D20-C20) -> 45.020821 | K20: =MEDIAN(J20:J22) -> 50.204125 | L20: 79.2024 | M20: =(G20-L20)/F20 -> 462.54079 | N20: =MEDIAN(M20:M22) -> 520.80678 | O20: =((G20-L20)*100)/(G20-C20) -> 96.158454 | P20: =MEDIAN(O20:O22) -> 96.239828 | Q20: =(L20-C20)/F20 -> 18.478583 | R20: =MEDIAN(Q20:Q22) -> 18.478583 | S20: =((L20-C20)*100)/(G20-C20) -> 3.8415464 | T20: =MEDIAN(S20:S22) -> 3.7601716
B21: 2 | C21: 84.3206 | D21: =113.2979 -> 113.2979 | E21: =D21-C21 -> 28.9773 | F21: =E21/$J$7 -> 0.027121191 | G21: 98.8684 | H21: =((G21-C21))/(F21) -> 536.39975 | J21: =((G21-C21)*100)/(D21-C21) -> 50.204125 | L21: 84.7435 | M21: =(G21-L21)/F21 -> 520.80678 | O21: =((G21-L21)*100)/(G21-C21) -> 97.093031 | Q21: =(L21-C21)/F21 -> 15.592973 | S21: =((L21-C21)*100)/(G21-C21) -> 2.9069688
B22: 3 | C22: 77.5887 | D22: =108.8399 -> 108.8399 | E22: =D22-C22 -> 31.2512 | F22: =E22/$J$7 -> 0.029249439 | G22: 93.4417 | H22: =((G22-C22))/(F22) -> 541.99331 | J22: =((G22-C22)*100)/(D22-C22) -> 50.727652 | L22: 78.1848 | M22: =(G22-L22)/F22 -> 521.61343 | O22: =((G22-L22)*100)/(G22-C22) -> 96.239828 | Q22: =(L22-C22)/F22 -> 20.379878 | S22: =((L22-C22)*100)/(G22-C22) -> 3.7601716
A26: Resultado TOC
A27: Amostra | C27: TOC (mg/L) | D27: TC (mg/L) | E27: IC (mg/L) | F27: TN (mg/L) | G27: diluicao | H27: TC (mg/L) | I27: media TC (mg/L) | J27: IC (mg/L) | K27: media IC (mg/L) | L27: TN (mg/L) | M27: media TN (mg/L)
A28: RA | B28: 1 | C28: 5.039 | D28: 5.044 | E28: 0.00562 | F28: 0.6891 | G28: 400 | H28: =D28*G28 -> 2017.6 | I28: =MEDIAN(H28:H29) -> 1778.6 | J28: =E28*G28 -> 2.248 | K28: =MEDIAN(J28:J29) -> 16.68 | L28: =F28*G28 -> 275.64 | M28: =MEDIAN(L28:L29) -> 281.76
B29: 2 | C29: 3.927 | D29: 3.849 | E29: 0.07778 | F29: 0.7197 | G29: 400 | H29: =D29*G29 -> 1539.6 | J29: =E29*G29 -> 31.112 | L29: =F29*G29 -> 287.88
A30: GL | B30: 1 | C30: 8.808 | D30: 8.812 | E30: 0.00431 | F30: 0.5875 | G30: 800 | H30: =D30*G30 -> 7049.6 | I30: =MEDIAN(H30:H31) -> 5523.2 | J30: =E30*G30 -> 3.448 | K30: =MEDIAN(J30:J31) -> 3.228 | L30: =F30*G30 -> 470 | M30: =MEDIAN(L30:L31) -> 488.6
B31: 2 | C31: 4.992 | D31: 4.996 | E31: 0.00376 | F31: 0.634 | G31: 800 | H31: =D31*G31 -> 3996.8 | J31: =E31*G31 -> 3.008 | L31: =F31*G31 -> 507.2

Sheet COV
A1: Substrato | B1: Densidade (g/L) | C1: TC (g/L) | D1: TN (g/L) | E1: TS (g/L) | F1: VS (g/L) | K1: Sub 1 | L1: Sub 2 | O1: Sub 1 | P1: Sub 2
A2: RA | B2: =Caracterizacao!J3 -> 1068.4376 | C2: =Caracterizacao!I28/1000 -> 1.7786 | D2: =Caracterizacao!M28/1000 -> 0.28176 | E2: =Caracterizacao!I14 -> 536.39975 | F2: =Caracterizacao!N14 -> 520.80678 | J2: Substrato | K2: RA | L2: Glucose | N2: Diluicao | O2: 10 | P2: 100
A3: GL – BIO | B3: =Caracterizacao!J5 -> 893.07404 | C3: =Caracterizacao!I30/1000 -> 5.5232 | D3: =Caracterizacao!M30/1000 -> 0.4886 | E3: =Caracterizacao!I17 -> 867.72399 | F3: =Caracterizacao!N17 -> 868.65482 | J3: Densidade (g/L) | K3: =INDEX($B$2:$B$100,MATCH($K$2,$A$2:$A$100,0)) -> 1068.4376 | L3: =INDEX($B$2:$B$100,MATCH($L$2,$A$2:$A$100,0)) -> 1540 | N3: Densidade ajustada (g/L) | O3: =K3/$O$2 -> 106.84376 | P3: =L3/$P$2 -> 15.4
A4: GL – PURO | B4: 126000 | C4: 493 | D4: 0 | E4: 1000 | F4: 1000 | J4: TC (g/L) | K4: =INDEX($C$2:$C$100,MATCH($K$2,$A$2:$A$100,0)) -> 1.7786 | L4: =INDEX($C$2:$C$100,MATCH($L$2,$A$2:$A$100,0)) -> 616 | N4: TC ajustado (g/L) | O4: =K4/$O$2 -> 0.17786 | P4: =L4/$P$2 -> 6.16
A5: Glucose | B5: 1540 | C5: 616 | D5: 0 | E5: 1540 | F5: 1540 | J5: TN (g/L) | K5: =INDEX($D$2:$D$100,MATCH($K$2,$A$2:$A$100,0)) -> 0.28176 | L5: =INDEX($D$2:$D$100,MATCH($L$2,$A$2:$A$100,0)) -> 0 | N5: TN ajustado (g/L) | O5: =K5/$O$2 -> 0.028176 | P5: =L5/$P$2 -> 0
J6: TS (g/L) | K6: =INDEX($E$2:$E$100,MATCH($K$2,$A$2:$A$100,0)) -> 536.39975 | L6: =INDEX($E$2:$E$100,MATCH($L$2,$A$2:$A$100,0)) -> 1540 | N6: TS ajustado (g/L) | O6: =K6/$O$2 -> 53.639975 | P6: =L6/$P$2 -> 15.4
J7: VS (g/L) | K7: =INDEX($F$2:$F$100,MATCH($K$2,$A$2:$A$100,0)) -> 520.80678 | L7: =INDEX($F$2:$F$100,MATCH($L$2,$A$2:$A$100,0)) -> 1540 | N7: VS ajustado (g/L) | O7: =K7/$O$2 -> 52.080678 | P7: =L7/$P$2 -> 15.4
I10: C/N Calculation
I12: Proporcao
I13: C | J13: 25
I14: N | J14: 1
I15: C/N | J15: =J13/J14 -> 25
I16: Volume Ratio (L) | J16: =((J15*P5)-P4)/(O4-(J15*O5)) -> 11.699016
I18: Volume (L) | K18: From V Ratio (L) | L18: Volume (mL) | M18: Quantidade Carbono (g) | O18: Concentracao Carbono (g/L)
I19: Sub 1 | J19: - | K19: =J16*J20 -> 0.11699016 | L19: =K19*1000 -> 116.99016 | M19: =K19*O4 -> 0.02080787 | O19: -
I20: Sub 2 | J20: 0.01 | K20: - | L20: =J20*1000 -> 10 | M20: =J20*P4 -> 0.0616 | O20: -
I21: Mistura | J21: =J20+K19 -> 0.12699016 | K21: - | L21: =J21*1000 -> 126.99016 | M21: =M19+M20 -> 0.08240787 | O21: =M21/J21 -> 0.64893114
I22: Sub 1 | J22: 0.1 | K22: - | L22: =J22*1000 -> 100 | M22: =J22*O3 -> 10.684376 | O22: -
I23: Sub 2 | J23: - | K23: =J22/J16 -> 0.0085477273 | L23: =K23*1000 -> 8.5477273 | M23: =K23*P3 -> 0.131635 | O23: -
I24: Mistura | J24: =J22+K23 -> 0.10854773 | K24: - | L24: =J24*1000 -> 108.54773 | M24: =M22+M23 -> 10.816011 | O24: =M24/J24 -> 99.642906
I27: Calculo ST e SV
I29: - | J29: Mass (g) | K29: Total Mass (g) | L29: TS (g) | M29: TS % | N29: VS (g) | O29: VS % | P29: VS/TS
I30: Sub 1 | J30: =K19*O3 -> 12.499669 | K30: =J30+J31 -> 12.653669 | L30: =($O$6*K19)+($P$6*J20) -> 6.4293494 | M30: =(L30/K30)*100 -> 50.81016 | N30: =($O$7*K19)+($P$7*J20) -> 6.246927 | O30: =(N30/K30)*100 -> 49.368504 | P30: =N30/L30 -> 0.97162661
I31: Sub 2 | J31: =J20*P3 -> 0.154
I32: Sub 1 | J32: =J22*O3 -> 10.684376 | K32: =J32+J33 -> 10.816011 | L32: =($O$6*K23)+($P$6*J22) -> 1.9984999 | M32: =(L32/K32)*100 -> 18.477236 | N32: =($O$7*K23)+($P$7*J22) -> 1.9851714 | O32: =(N32/K32)*100 -> 18.354007 | P32: =N32/L32 -> 0.99333077
I33: Sub 2 | J33: =K23*P3 -> 0.131635
I36: Calculo COV
I38: Diluicao | L38: TS (g/L) | M38: VS (g/L)
I39: 1 estagio | J39: 1 | L39: =L30/(J20+K19) -> 50.62872 | M39: =N30/(J20+K19) -> 49.192212
I40: 2 estagios | J40: 1 | L40: =L32/(J22+K23) -> 18.411255 | M40: =N32/(J22+K23) -> 18.288466
I42: Reator | J42: Volume (L) | K42: Volume (m^3) | L42: Tempo Retencao (d) | M42: Fluxo (L/d) | N42: VS (g/d) | O42: VS (Kg/d) | P42: COV (Kg SV/m³ d)
I43: Reator Pequeno 1 | J43: 1 | K43: =J43/1000 -> 0.001 | L43: 30 | M43: =J43/L43 -> 0.033333333 | N43: =M43*($M$39/J39) -> 1.6397404 | O43: =N43/1000 -> 0.0016397404 | P43: =O43*(1/K43) -> 1.6397404 | Q43: 4-8
I44: Reator Pequeno 2 | J44: 1 | K44: =J44/1000 -> 0.001 | L44: 3 | M44: =J44/L44 -> 0.33333333 | N44: =M44*($M$39/J40) -> 16.397404 | O44: =N44/1000 -> 0.016397404 | P44: =O44*(1/K44) -> 16.397404
I45: Reator Grande | J45: 4 | K45: =J45/1000 -> 0.004 | L45: 12 | M45: =J45/L45 -> 0.33333333 | N45: =M45*($M$39/J40) -> 16.397404 | O45: =N45/1000 -> 0.016397404 | P45: =O45*(1/K45) -> 4.099351
N46: =M43*($M$40/J39) -> 0.60961554 | O46: =N46/1000 -> 0.00060961554 | P46: =O46*(1/K43) -> 0.60961554 | Q46: 4-8
I47: Calculo para montar a solucao | N47: =M44*($M$40/J40) -> 6.0961554 | O47: =N47/1000 -> 0.0060961554 | P47: =O47*(1/K44) -> 6.0961554
N48: =M45*($M$40/J40) -> 6.0961554 | O48: =N48/1000 -> 0.0060961554 | P48: =O48*(1/K45) -> 1.5240388
I49: 100 | J49: Volume (mL) | K49: mL | L49: g
I50: Sub 1 | J50: =$L$19/$L$21 -> 0.92125374 | K50: =J50*$I$49 -> 92.125374 | L50: =K50*($O$3/1000) -> 9.8430214
I51: Sub 2 | J51: =$L$20/$L$21 -> 0.078746257 | K51: =J51*$I$49 -> 7.8746257 | L51: =K51*($P$3/1000) -> 0.12126924
...

Sheet Calibracao Bombas
A1: bomba grande A | B1: mL/min | C1: rpm | D1: volume (mL) | J1: bomba pequena | L1: rpm | M1: volume (mL)
A2: Diogenes | B2: 0.3133 | C2: 0.1 | D2: 0.3 | L2: 1 | M2: 1.5
B3: 0.4 | C3: 0.128 | D3: 0.4 | L3: 5 | M3: 4
B4: 0.5 | C4: 0.16 | D4: 0.45 | L4: 10 | M4: 8.9
B5: 0.6 | C5: 0.191 | D5: 0.59 | L5: 15 | M5: 13.3
B6: 0.75 | C6: 0.239 | D6: 0.67 | L6: 20 | M6: 17.5
B7: 0.8 | C7: 0.255 | D7: 0.92 | L7: 30 | M7: 26
B8: 0.9 | C8: 0.287 | D8: 1.14 | L8: 50 | M8: 44
B9: 1 | C9: 0.319 | D9: 1.16 | L9: 80 | M9: 69
B10: 1.25 | C10: 0.399 | D10: 1.35 | L10: 100 | M10: 87
B11: 1.5 | C11: 0.479 | D11: 1.43 | L11: 120 | M11: 104
B12: 1.75 | C12: 0.559 | D12: 1.67 | L12: 200 | M12: 168
A25: bomba grande B | B25: mL/min | C25: rpm | D25: volume (mL) | J25: bomba grande C | K25: mL/min | L25: rpm | M25: volume (mL)
A26: Verena entrada | J26: medido em 30 s
J27: Verena saida
H53: verena
E54: reator diogenes | H54: reator pequeno | K54: reator grande
A55: quant ativacoes | B55: 1 | D55: tempo rentencao (dia) | E55: 30 | H55: 3 | K55: 12
A56: tempo ativacao (min) | B56: 4 | D56: volume (mL) | E56: 1000 | H56: 1000 | K56: 4000
D57: volume/dia (mL) | E57: =E56/E55 -> 33.333333 | H57: =H56/H55 -> 333.33333 | K57: =K56/K55 -> 333.33333
D58: volume/ativacao (mL) | E58: =E57/$B$55 -> 33.333333 | H58: =H57/$B$55 -> 333.33333 | K58: =K57/$B$55 -> 333.33333
D59: volume/minuto (mL) | E59: =E58/$B$56 -> 8.3333333 | H59: =H58/$B$56 -> 83.333333 | K59: =K58/($B$56*2) -> 41.666667
D60: curva bomba a | E60: {=LINEST(C2:C12,D2:D12)} -> 0.30530654 | F60: 0.0035009131 | H60: {=LINEST(C26:C36,D26:D36)} -> #VALUE! | I60: #VALUE! | K60: {=LINEST(L26:L36,M26:M36)} -> #VALUE! | L60: #VALUE!
D61: rpm | E61: =(E59*E60)+F60 -> 2.5477221 | H61: =(H59*H60)+I60 -> #VALUE! | K61: =(K59*K60)+L60 -> #VALUE!
D62: Curva 2 bomba a | E62: {=LINEST(B2:B12,C2:C12)} -> 3.1310818 | F62: 0.00062263595 | H62: {=LINEST(B26:B36,C26:C36)} -> #VALUE! | I62: #VALUE! | K62: {=LINEST(K26:K36,L26:L36)} -> #VALUE! | L62: #VALUE!
D63: mL/min | E63: =(E62*E61)+F62 -> 7.9777491 | H63: =(H62*H61)+I62 -> #VALUE! | K63: =(K62*K61)+L62 -> #VALUE!

Sheet Nutrientes
A1: Nutrientes | B1: Mass (mg/350ml) | C1: Adição (mg/L) | D1: Adição (g/L) | E1: X100 (g/L) | F1: X1000 (g/L) | G1: X2000 (g/L)
A2: MgSO4.7H2O | B2: 18.9 | C2: =((B2*1000)/350) -> 54 | D2: =((B2*1000)/350)/1000 -> 0.054 | E2: =D2*100 -> 5.4 | F2: =D2*1000 -> 54 | G2: =D2*2000 -> 108
A3: FeSO4.7H2O | B3: 522.8 | C3: =((B3*1000)/350) -> 1493.7143 | D3: =((B3*1000)/350)/1000 -> 1.4937143 | E3: =D3*100 -> 149.37143 | F3: =D3*1000 -> 1493.7143 | G3: =D3*2000 -> 2987.4286
A4: CoCl2.6H2O | B4: 0.42 | C4: =((B4*1000)/350) -> 1.2 | D4: =((B4*1000)/350)/1000 -> 0.0012 | E4: =D4*100 -> 0.12 | F4: =D4*1000 -> 1.2 | G4: =D4*2000 -> 2.4
A5: ZnCl2 | B5: 10.5 | C5: =((B5*1000)/350) -> 30 | D5: =((B5*1000)/350)/1000 -> 0.03 | E5: =D5*100 -> 3 | F5: =D5*1000 -> 30 | G5: =D5*2000 -> 60
A6: NiCl2.6H2O | B6: 0.0105 | C6: =((B6*1000)/350) -> 0.03 | D6: =((B6*1000)/350)/1000 -> 3e-05 | E6: =D6*100 -> 0.003 | F6: =D6*1000 -> 0.03 | G6: =D6*2000 -> 0.06
A7: EDTA | B7: 0.21 | C7: =((B7*1000)/350) -> 0.6 | D7: =((B7*1000)/350)/1000 -> 0.0006 | E7: =D7*100 -> 0.06 | F7: =D7*1000 -> 0.6 | G7: =D7*2000 -> 1.2
A8: CuSO4.5H2O | B8: 9.23 | C8: =((B8*1000)/350) -> 26.371429 | D8: =((B8*1000)/350)/1000 -> 0.026371429 | E8: =D8*100 -> 2.6371429 | F8: =D8*1000 -> 26.371429 | G8: =D8*2000 -> 52.742857
A11: mL | B11: g/L
A12: 500 | B12: 1X | C12: 100X | D12: 1000X | E12: 2000X
A13: MgSO4.7H2O | B13: =D2*($A$12/1000) -> 0.027 | C13: =(E2*$A$12)/1000 -> 2.7 | D13: =(F2*$A$12)/1000 -> 27 | E13: =(G2*$A$12)/1000 -> 54
A14: FeSO4.7H2O | B14: =D3*($A$12/1000) -> 0.74685714 | C14: =(E3*$A$12)/1000 -> 74.685714 | D14: =(F3*$A$12)/1000 -> 746.85714 | E14: =(G3*$A$12)/1000 -> 1493.7143
A15: CoCl2.6H2O | B15: =D4*($A$12/1000) -> 0.0006 | C15: =(E4*$A$12)/1000 -> 0.06 | D15: =(F4*$A$12)/1000 -> 0.6 | E15: =(G4*$A$12)/1000 -> 1.2
A16: ZnCl2 | B16: =D5*($A$12/1000) -> 0.015 | C16: =(E5*$A$12)/1000 -> 1.5 | D16: =(F5*$A$12)/1000 -> 15 | E16: =(G5*$A$12)/1000 -> 30
A17: NiCl2.6H2O | B17: =D6*($A$12/1000) -> 1.5e-05 | C17: =(E6*$A$12)/1000 -> 0.0015 | D17: =(F6*$A$12)/1000 -> 0.015 | E17: =(G6*$A$12)/1000 -> 0.03
A18: EDTA | B18: =D7*($A$12/1000) -> 0.0003 | C18: =(E7*$A$12)/1000 -> 0.03 | D18: =(F7*$A$12)/1000 -> 0.3 | E18: =(G7*$A$12)/1000 -> 0.6
A19: CuSO4.5H2O | B19: =D8*($A$12/1000) -> 0.013185714 | C19: =(E8*$A$12)/1000 -> 1.3185714 | D19: =(F8*$A$12)/1000 -> 13.185714 | E19: =(G8*$A$12)/1000 -> 26.371429
A20: mL | B20: =C20*100 -> 500 | C20: =D20*10 -> 5 | D20: =1*(A12/1000) -> 0.5 | E20: =D20/2 -> 0.25
A23: mL | B23: g/L
A24: 100 | B24: 1X | C24: 100X | D24: 1000X | E24: 2000X
A25: MgSO4.7H2O | B25: =D2*($A$24/1000) -> 0.0054 | C25: =(E2*$A$24)/1000 -> 0.54 | D25: =(F2*$A$24)/1000 -> 5.4 | E25: =(G2*$A$24)/1000 -> 10.8
A26: FeSO4.7H2O | B26: =D3*($A$24/1000) -> 0.14937143 | C26: =(E3*$A$24)/1000 -> 14.937143 | D26: =(F3*$A$24)/1000 -> 149.37143 | E26: =(G3*$A$24)/1000 -> 298.74286
A27: CoCl2.6H2O | B27: =D4*($A$24/1000) -> 0.00012 | C27: =(E4*$A$24)/1000 -> 0.012 | D27: =(F4*$A$24)/1000 -> 0.12 | E27: =(G4*$A$24)/1000 -> 0.24
A28: ZnCl2 | B28: =D5*($A$24/1000) -> 0.003 | C28: =(E5*$A$24)/1000 -> 0.3 | D28: =(F5*$A$24)/1000 -> 3 | E28: =(G5*$A$24)/1000 -> 6
A29: NiCl2.6H2O | B29: =D6*($A$24/1000) -> 3e-06 | C29: =(E6*$A$24)/1000 -> 0.0003 | D29: =(F6*$A$24)/1000 -> 0.003 | E29: =(G6*$A$24)/1000 -> 0.006
A30: EDTA | B30: =D7*($A$24/1000) -> 6e-05 | C30: =(E7*$A$24)/1000 -> 0.006 | D30: =(F7*$A$24)/1000 -> 0.06 | E30: =(G7*$A$24)/1000 -> 0.12
A31: CuSO4.5H2O | B31: =D8*($A$24/1000) -> 0.0026371429 | C31: =(E8*$A$24)/1000 -> 0.26371429 | D31: =(F8*$A$24)/1000 -> 2.6371429 | E31: =(G8*$A$24)/1000 -> 5.2742857
A32: mL | B32: =C32*100 -> 100 | C32: =D32*10 -> 1 | D32: =1*(A24/1000) -> 0.1 | E32: =D32/2 -> 0.05
A35: mL | B35: g/L
A36: 2000 | B36: 1X | C36: 100X | D36: 1000X | E36: 2000X
A37: MgSO4.7H2O | B37: =D2*($A$36/1000) -> 0.108 | C37: =(E2*$A$36)/1000 -> 10.8 | D37: =(F2*$A$36)/1000 -> 108 | E37: =(G2*$A$36)/1000 -> 216
A38: FeSO4.7H2O | B38: =D3*($A$36/1000) -> 2.9874286 | C38: =(E3*$A$36)/1000 -> 298.74286 | D38: =(F3*$A$36)/1000 -> 2987.4286 | E38: =(G3*$A$36)/1000 -> 5974.8571
A39: CoCl2.6H2O | B39: =D4*($A$36/1000) -> 0.0024 | C39: =(E4*$A$36)/1000 -> 0.24 | D39: =(F4*$A$36)/1000 -> 2.4 | E39: =(G4*$A$36)/1000 -> 4.8
A40: ZnCl2 | B40: =D5*($A$36/1000) -> 0.06 | C40: =(E5*$A$36)/1000 -> 6 | D40: =(F5*$A$36)/1000 -> 60 | E40: =(G5*$A$36)/1000 -> 120
A41: NiCl2.6H2O | B41: =D6*($A$36/1000) -> 6e-05 | C41: =(E6*$A$36)/1000 -> 0.006 | D41: =(F6*$A$36)/1000 -> 0.06 | E41: =(G6*$A$36)/1000 -> 0.12
A42: EDTA | B42: =D7*($A$36/1000) -> 0.0012 | C42: =(E7*$A$36)/1000 -> 0.12 | D42: =(F7*$A$36)/1000 -> 1.2 | E42: =(G7*$A$36)/1000 -> 2.4
A43: CuSO4.5H2O | B43: =D8*($A$36/1000) -> 0.052742857 | C43: =(E8*$A$36)/1000 -> 5.2742857 | D43: =(F8*$A$36)/1000 -> 52.742857 | E43: =(G8*$A$36)/1000 -> 105.48571
A44: mL | B44: =C44*100 -> 2000 | C44: =D44*10 -> 20 | D44: =1*(A36/1000) -> 2 | E44: =D44/2 -> 1
